File: raw_data.csv
,Info_Author,Info_Title,DOI,Info_Journal,Info_Volume,Info_Pages,Info_Received,Info_Material_ID,Info_Sample_ID,Info_Test_ID,Info_Origin,Info_Notes,Ag(at%),Al(at%),Au(at%),B(at%),Bi(at%),Ce(at%),Co(at%),Cr(at%),Cu(at%),Dy(at%),Er(at%),Fe(at%),Gd(at%),Hf(at%),In(at%),La(at%),Mn(at%),Mo(at%),Nb(at%),Nd(at%),Ni(at%),Pb(at%),Pd(at%),Pr(at%),Pt(at%),Re(at%),Rh(at%),Sb(at%),Sc(at%),Si(at%),Sn(at%),Ta(at%),Te(at%),Ti(at%),Tl(at%),V(at%),W(at%),Y(at%),Zr(at%),Processing_BPHT_Temp,Processing_BPHT_Time,Processing_Rolling_Temp,Processing_HR_Red,Processing_CR_Red,Processing_Extrusion_Temp,Processing_Extrusion_Area_Reduction(%),Processing_APHT_Temp,Processing_APHT_Time,Processing_APHT_Method,Processing_FinalHT_Temp,Processing_FinalHT_Time,Processing_FinalHT_Method,SME_Test_Applied_Stress(MPa),SME_Test_Applied_Bend_Strain(%),SME_Test_LCT,SME_Test_UCT,SME_Test_Temp_Rate,SME_Test_Cycle,SE_Test_Temperature_Above_Af(Temp-Af),SE_Test_Strain_Rate(/s),SE_Test_Displacement_Rate(mm/s),SE_Test_Cycle,MSM_Test_Curie_Temperature,MSM_Test_Applied_Magnetic_Field(T),MSM_Test_Mag_Test_Temp(C),Hard_Param_VHTemp,Hard_Param_VHMass,Hard_Param_VHTime,Micro_Grain Size(nm),Micro_Matrix_Comp,Micro_e/a_ratio,Micro_cv_concentration,Micro_Parent_Test_Temperature_Above_Af(Temp-Af),Micro_Parent_Structure,Micro_Parent_a_(A),Micro_Parent_b,Micro_Parent_c,Micro_Parent_Space_Group,Micro_Intermediate_Test_Temperature_Above_Af(Temp-Af),Micro_Intermediate_Structure,Micro_Intermediate_a_(A),Micro_Intermediate_b,Micro_Intermediate_c,Micro_Intermediate_Space_Group,Micro_Martensite_Test_Temperature_Above_Af(Temp-Af),Micro_Martensite_Structure,Micro_Martensite_a_(A),Micro_Martensite_b,Micro_Martensite_c,Micro_Martensite_Beta,Micro_Martensite_Space_Group,Micro_Martensite_Sub-structure,Micro_Precipitate_Test_Temperature,Micro_Precipitate_Structure,Micro_Precipitate_Volume_Fraction,NeedsAttention,SME_Transforms,SME_Mf,SME_Mp,SME_Ms,SME_As,SME_Ap,SME_Af,SME_Thermal_Hysteresis,SME_Transformation_Range,SME_RfM,SME_RfA,SME_dH(MA)(J/g),SME_dH(AM)(J/g),SME_dH(AR)(J/G),SME_dS(MA)(J/kgK),SME_dS(AM)(J/kgK),SME_dS(AR)(J/kgK),SME_epsilonAct(%),SME_epsilonIrr(%),SME_Failure(FatigueTest),SME_Bend_Recovery(%),SE_R.Strain(%),SE_Strain_Max(%),SE_Stress_Max(MPa),SE_Mf_Stress,SE_Ms_Stress,SE_As_Stress,SE_Af_Stress,SE_M_Yield,SE_A_Yield,MSME_Magnetization (emu/g),MSME_Magnetization Change (AM)(emu/g),MSME_Magnetization Change (MA)(emu/g),MSME_Mf Temp (Â°C),MSME_Mf Mag (emu/g),MSME_Mp Temp (Â°C),MSME_Mp Mag (emu/g),MSME_Ms_Temp(C),MSME_Ms_Mag(emu/g),MSME_Direct average rate (emu/gÂ°C),MSME_Direct_integrated_magnetization_change(emu/g),MSME_As_Temp(C),MSME_As_Mag(emu/g),MSME_Ap_Temp (C),MSME_Ap_Mag(emu/g),MSME_Af_Temp (C),MSME_Af_Mag(emu/g),MSME_Reverse_average_rate(emu/gC),MSME_Reverse_integrated_magnetization_change(emu/g),MSME_Direct_MT_range(C),MSME_Reverse_MT_range(C),MSME_Hysteresis(C),MSME_Estimated_entropy_difference_(J/kg*K),"MSME_Tc(DSC)-Ms(SQUID,0.05T)",Hard_VHN
0,"Can, Karaman",,,,,,,,,12,Internal,2 heating & cooling cycles. No transformation observed.,0.0,0.0,0.0,0.0,0,0.0,0.0,0.0,0.0,0,0.0,0.0,0.0,0.0,0.0,0.0,0.0,0.0,0.0,0.0,27.0,0,25.0,0.0,0.0,0.0,0,0,0.0,0,0.0,0.0,0,48.0,0,0.0,0.0,0.0,0.0,20.0,0.0,900,50,0.0,20,0.0,20.0,0.0,0,20.0,0.0,0,0.0,0,100,300,10.0,3,30,0.0,0.0,1,,,,,,,,,,,,,,,,,,,,,,,,,,,,,,,,,,,,,,,,,,,,,,0,0,0,,,,,,,,,,,,,,,,,,,,,,,,,,,,,,,,,,,,,,,,,
1,"Can, Karaman",,,,,,,,,26,Internal,Did 2 heating&cooling cycles at 50 and 100 Mpa. Also did 1 heating&cooling cycle at 150MPa. No transformation was detected.,0.0,0.0,0.0,0.0,0,0.0,0.0,0.0,0.0,0,0.0,0.0,0.0,0.0,0.0,0.0,0.0,0.0,0.0,0.0,27.0,0,25.0,0.0,0.0,0.0,0,0,0.0,0,0.0,0.0,0,48.0,0,0.0,0.0,0.0,0.0,20.0,0.0,900,50,0.0,20,0.0,20.0,0.0,0,20.0,0.0,0,50.0,0,100,300,10.0,1,30,0.0,0.0,1,,,,,,,,,,,,,,,,,,,,,,,,,,,,,,,,,,,,,,,,,,,,,,0,0,0,,,,,,,,,,,,,,,,,,,,,,,,,,,,,,,,,,,,,,,,,
2,"Can, Karaman",,,,,,,,,26,Internal,Did 2 heating&cooling cycles at 50 and 100 Mpa. Also did 1 heating&cooling cycle at 150MPa. No transformation was detected.,0.0,0.0,0.0,0.0,0,0.0,0.0,0.0,0.0,0,0.0,0.0,0.0,0.0,0.0,0.0,0.0,0.0,0.0,0.0,27.0,0,25.0,0.0,0.0,0.0,0,0,0.0,0,0.0,0.0,0,48.0,0,0.0,0.0,0.0,0.0,20.0,0.0,900,50,0.0,20,0.0,20.0,0.0,0,20.0,0.0,0,100.0,0,100,300,10.0,2,30,0.0,0.0,1,,,,,,,,,,,,,,,,,,,,,,,,,,,,,,,,,,,,,,,,,,,,,,0,0,0,,,,,,,,,,,,,,,,,,,,,,,,,,,,,,,,,,,,,,,,,
3,"Can, Karaman",,,,,,,,,26,Internal,Did 2 heating&cooling cycles at 50 and 100 Mpa. Also did 1 heating&cooling cycle at 150MPa. No transformation was detected.,0.0,0.0,0.0,0.0,0,0.0,0.0,0.0,0.0,0,0.0,0.0,0.0,0.0,0.0,0.0,0.0,0.0,0.0,0.0,27.0,0,25.0,0.0,0.0,0.0,0,0,0.0,0,0.0,0.0,0,48.0,0,0.0,0.0,0.0,0.0,20.0,0.0,900,50,0.0,20,0.0,20.0,0.0,0,20.0,0.0,0,150.0,0,100,300,10.0,3,30,0.0,0.0,1,,,,,,,,,,,,,,,,,,,,,,,,,,,,,,,,,,,,,,,,,,,,,,0,0,0,,,,,,,,,,,,,,,,,,,,,,,,,,,,,,,,,,,,,,,,,
4,"Demblon, Karaman",,,,,,,,,,Internal,,0.0,0.0,0.0,0.0,0,0.0,0.0,0.0,0.0,0,0.0,0.0,0.0,18.0,0.0,0.0,0.0,0.0,0.0,0.0,50.7,0,0.0,0.0,0.0,0.0,0,0,0.0,0,0.0,0.0,0,31.3,0,0.0,0.0,0.0,0.0,20.0,0.0,20,0,0.0,20,0.0,20.0,0.0,0,1050.0,2.0,0,0.0,0,,,10.0,3,30,0.0,0.0,1,,,,,,,,,,,,,,,,,,,,,,,,,,,,,,,,,,,,,,,,,,,,,,0,0,0,,,,,,,,,,,,,,,,,,,,,,,,,,,,,,,,,,,,,,,,,
6,"Demblon, Karaman",,,,,,,,,,Internal,,0.0,0.0,0.0,0.0,0,0.0,0.0,0.0,0.0,0,0.0,0.0,0.0,17.0,0.0,0.0,0.0,0.0,0.0,0.0,50.8,0,0.0,0.0,0.0,0.0,0,0,0.0,0,0.0,0.0,0,32.2,0,0.0,0.0,0.0,0.0,20.0,0.0,20,0,0.0,20,0.0,20.0,0.0,0,1050.0,2.0,0,0.0,0,,,10.0,3,30,0.0,0.0,1,,,,,,,,,,,,,,,,,,,,,,,,,,,,,,,,,,,,,,,,,,,,,,0,0,0,,,,,,,,,,,,,,,,,,,,,,,,,,,,,,,,,,,,,,,,,
8,"Demblon, Karaman",,,,,,,,,,Internal,,0.0,0.0,0.0,0.0,0,0.0,0.0,0.0,0.0,0,0.0,0.0,0.0,17.0,0.0,0.0,0.0,0.0,0.0,0.0,50.9,0,0.0,0.0,0.0,0.0,0,0,0.0,0,0.0,0.0,0,32.1,0,0.0,0.0,0.0,0.0,20.0,0.0,20,0,0.0,20,0.0,20.0,0.0,0,1050.0,2.0,0,0.0,0,,,10.0,3,30,0.0,0.0,1,,,,,,,,,,,,,,,,,,,,,,,,,,,,,,,,,,,,,,,,,,,,,,0,0,0,,,,,,,,,,,,,,,,,,,,,,,,,,,,,,,,,,,,,,,,,
10,"Demblon, Karaman",,,,,,,,,,Internal,,0.0,0.0,0.0,0.0,0,0.0,0.0,0.0,0.0,0,0.0,0.0,0.0,17.0,0.0,0.0,0.0,0.0,0.0,0.0,51.0,0,0.0,0.0,0.0,0.0,0,0,0.0,0,0.0,0.0,0,32.0,0,0.0,0.0,0.0,0.0,20.0,0.0,20,0,0.0,20,0.0,20.0,0.0,0,1050.0,2.0,0,0.0,0,,,10.0,3,30,0.0,0.0,1,,,,,,,,,,,,,,,,,,,,,,,,,,,,,,,,,,,,,,,,,,,,,,0,0,0,,,,,,,,,,,,,,,,,,,,,,,,,,,,,,,,,,,,,,,,,
12,"Demblon, Karaman",,,,,,,,,,Internal,,0.0,0.0,0.0,0.0,0,0.0,0.0,0.0,0.0,0,0.0,0.0,0.0,19.0,0.0,0.0,0.0,0.0,0.0,0.0,51.0,0,0.0,0.0,0.0,0.0,0,0,0.0,0,0.0,0.0,0,30.0,0,0.0,0.0,0.0,0.0,20.0,0.0,20,0,0.0,20,0.0,20.0,0.0,0,1050.0,2.0,0,0.0,0,,,10.0,3,30,0.0,0.0,1,,,,,,,,,,,,,,,,,,,,,,,,,,,,,,,,,,,,,,,,,,,,,,0,0,0,,,,,,,,,,,,,,,,,,,,,,,,,,,,,,,,,,,,,,,,,
14,"Salas, Karaman",,,,,,,,,,Internal,2016Q PC In13.6 FC,0.0,0.0,0.0,0.0,0,0.0,5.0,0.0,0.0,0,0.0,0.0,0.0,0.0,13.78,0.0,36.09,0.0,0.0,0.0,45.14,0,0.0,0.0,0.0,0.0,0,0,0.0,0,0.0,0.0,0,0.0,0,0.0,0.0,0.0,0.0,900.0,24.0,20,0,0.0,20,0.0,900.0,1.0,48,400.0,3.0,0,0.0,0,,,10.0,3,30,0.0,0.0,1,124.86,0.05,,,,,,,,,,B2/L21,,,,Pm-3m/Fm-3m,,,,,,,,L10,,,,,P4/mmm,Modulations,,,,,,-81.4,-75.43,-72.39,-52.22,-44.68,-40.74,31.65,40.66,,,1.4,0.62,,-6.17,3.18,,,,,,,,,,,,,,,,53.95,52.61,-102.87,14.3,-75.41,56.61,-73.75,68.25,1.85,57.41,-65.46,13.62,-47.86,50.81,-44.57,66.23,2.52,57.82,29.12,20.89,28.37,-9.45,198.61,
16,"Salas, Karaman",,,,,,,,,,Internal,2016Q PC In13.3 WQ,0.0,0.0,0.0,0.0,0,0.0,5.05,0.0,0.0,0,0.0,0.0,0.0,0.0,13.55,0.0,36.42,0.0,0.0,0.0,44.97,0,0.0,0.0,0.0,0.0,0,0,0.0,0,0.0,0.0,0,0.0,0,0.0,0.0,0.0,0.0,20.0,0.0,20,0,0.0,20,0.0,900.0,24.0,0,300.0,3.0,0,0.0,0,,,10.0,3,30,0.0,0.0,1,125.18,0.05,,,,,,,,,,B2/L21,6.01,,,Pm-3m/Fm-3m,,,,,,,,L10,,,,,P4/mmm,Modulations,,,,,,-94.6,-85.96,-68.5,-55.72,-51.29,-48.58,19.92,46.02,,,0.51,0.86,,-2.29,4.48,,,,,,,,,,,,,,,,87.67,87.78,-104.91,23.98,-87.76,73.64,-82.77,111.65,3.96,94.05,-65.12,23.68,-51.78,87.27,-48.77,111.46,5.37,95.53,22.13,16.35,34.99,-7.36,207.95,
18,"Salas, Karaman",,,,,,,,,,Internal,2016Q PC In13.6 FC,0.0,0.0,0.0,0.0,0,0.0,5.0,0.0,0.0,0,0.0,0.0,0.0,0.0,13.78,0.0,36.09,0.0,0.0,0.0,45.14,0,0.0,0.0,0.0,0.0,0,0,0.0,0,0.0,0.0,0,0.0,0,0.0,0.0,0.0,0.0,900.0,24.0,20,0,0.0,20,0.0,900.0,1.0,48,400.0,24.0,0,0.0,0,,,10.0,3,30,0.0,0.0,1,124.67,0.05,,,,,,,,,,B2/L21,,,,Pm-3m/Fm-3m,,,,,,,,L10,,,,,P4/mmm,Modulations,,,,,,-74.89,-68.31,-65.02,-48.1,-41,-37.36,27.66,37.53,,,1.69,1.05,,-7.34,5.2,,,,,,,,,,,,,,,,96.78,97.03,-84.63,13.06,-63.24,90.53,-61.81,109.84,4.24,106.18,-56.54,11.02,-42.3,72.3,-40.13,108.06,5.91,106.55,22.81,16.41,21.32,-9.22,186.48,
20,"Salas, Karaman",,,,,,,,,,Internal,2016Q PC In13.6 FC,0.0,0.0,0.0,0.0,0,0.0,5.0,0.0,0.0,0,0.0,0.0,0.0,0.0,13.78,0.0,36.09,0.0,0.0,0.0,45.14,0,0.0,0.0,0.0,0.0,0,0,0.0,0,0.0,0.0,0,0.0,0,0.0,0.0,0.0,0.0,900.0,24.0,20,0,0.0,20,0.0,900.0,1.0,48,400.0,0.5,0,0.0,0,,,10.0,3,30,0.0,0.0,1,124.74,0.05,,,,,,,,,,B2/L21,,,,Pm-3m/Fm-3m,,,,,,,,L10,,,,,P4/mmm,Modulations,,,,,,-76.82,-69.47,-55.53,-48.11,-41.69,-38.3,17.23,38.52,,,1.67,1.08,,-7.26,5.29,,,,,,,,,,,,,,,,89.64,84.37,-87.05,11.55,-62.73,78,-61.41,101.18,3.5,96.88,-58.63,10.13,-44.31,63.35,-40.7,94.51,4.71,94.27,25.64,17.93,19.57,-7.87,186.15,
22,"Salas, Karaman",,,,,,,,,,Internal,2016Q PC In13.6 WQ,0.0,0.0,0.0,0.0,0,0.0,5.0,0.0,0.0,0,0.0,0.0,0.0,0.0,13.78,0.0,36.09,0.0,0.0,0.0,45.14,0,0.0,0.0,0.0,0.0,0,0,0.0,0,0.0,0.0,0,0.0,0,0.0,0.0,0.0,0.0,20.0,0.0,20,0,0.0,20,0.0,900.0,24.0,0,500.0,0.25,0,0.0,0,,,10.0,3,30,0.0,0.0,1,118.04,0.05,,,,,,,,,,B2/L21,,,,Pm-3m/Fm-3m,,,,,,,,L10,,,,,P4/mmm,Modulations,,,,,,-81.14,-76.13,-69.06,-55.01,-48.89,-42.97,26.09,38.17,,,1.78,1.11,,-7.96,5.63,,,,,,,,,,,,,,,,66.52,64.09,-93.5,11.13,-76.38,50.41,-70.89,77.65,2.94,72.56,-63.6,11.08,-50.54,53.1,-46.13,75.17,3.67,70.11,22.61,17.47,25.3,-8.58,188.93,
24,"Salas, Karaman",,,,,,,,,,Internal,2016Q PC In13.5 FC,0.0,0.0,0.0,0.0,0,0.0,5.04,0.0,0.0,0,0.0,0.0,0.0,0.0,13.71,0.0,36.09,0.0,0.0,0.0,45.16,0,0.0,0.0,0.0,0.0,0,0,0.0,0,0.0,0.0,0,0.0,0,0.0,0.0,0.0,0.0,900.0,24.0,20,0,0.0,20,0.0,900.0,1.0,24,400.0,24.0,0,0.0,0,,,10.0,3,30,0.0,0.0,1,123.69,0.05,,,,,,,,,,B2/L21,,,,Pm-3m/Fm-3m,,,,,,,,L10,,,,,P4/mmm,Modulations,,,,,,-47.99,-44.09,-42.34,-26.3,-22.09,-18.81,23.53,29.18,,,2.49,1.35,,-9.92,5.9,,,,,,,,,,,,,,,,90.62,87.81,-59.98,9.59,-43.3,63.44,-39.86,100.21,4.5,99.44,-34.44,9.36,-25.33,59.34,-20.51,97.18,6.3,96.63,20.12,13.94,18.66,-9.12,163.55,
26,"Salas, Karaman",,,,,,,,,,Internal,2016Q PC In13.7 WQ,0.0,0.0,0.0,0.0,0,0.0,5.01,0.0,0.0,0,0.0,0.0,0.0,0.0,13.98,0.0,36.09,0.0,0.0,0.0,44.97,0,0.0,0.0,0.0,0.0,0,0,0.0,0,0.0,0.0,0,0.0,0,0.0,0.0,0.0,0.0,20.0,0.0,20,0,0.0,20,0.0,900.0,24.0,0,450.0,72.0,0,0.0,0,,,10.0,3,30,0.0,0.0,1,119.59,0.05,,,,,,,,,,B2/L21,,,,Pm-3m/Fm-3m,,,,,,,,L10,,,,,P4/mmm,Modulations,,,,,,-77.79,-71.68,-65.34,-49.69,-45.14,-39.25,26.09,38.54,,,1.99,1.44,,-8.71,7.16,,,,,,,,,,,,,,,,79.96,80.63,-84.85,14.57,-75.39,46.78,-67.05,94.53,4.49,87.54,-55.98,12.22,-46.76,57.69,-43.03,92.85,6.23,88.54,17.8,12.95,26.32,-10.6,186.64,
28,"Salas, Karaman",,,,,,,,,,Internal,2016Q PC In13.5 WQ,0.0,0.0,0.0,0.0,0,0.0,5.04,0.0,0.0,0,0.0,0.0,0.0,0.0,13.71,0.0,36.09,0.0,0.0,0.0,45.16,0,0.0,0.0,0.0,0.0,0,0,0.0,0,0.0,0.0,0,0.0,0,0.0,0.0,0.0,0.0,20.0,0.0,20,0,0.0,20,0.0,900.0,24.0,0,400.0,72.0,0,0.0,0,,,10.0,3,30,0.0,0.0,1,124.5,0.05,,,,,,,,,,B2/L21,,,,Pm-3m/Fm-3m,,,,,,,,L10,,,,,P4/mmm,Modulations,,,,,,-45.25,-36.71,-35.97,-20.6,-16.03,-13.88,22.09,31.37,,,2.56,1.49,,-10,6.38,,,,,,,,,,,,,,,,35.18,35.93,-60.41,10.88,-39.25,36.86,-36.24,46.06,1.46,36.78,-30.37,8.24,-18.25,33.23,-16.29,44.16,2.55,38.32,24.17,14.08,20.48,-13.01,160.74,
30,"Salas, Karaman",,,,,,,,,,Internal,2016Q PC In13.6 FC,0.0,0.0,0.0,0.0,0,0.0,5.0,0.0,0.0,0,0.0,0.0,0.0,0.0,13.78,0.0,36.09,0.0,0.0,0.0,45.14,0,0.0,0.0,0.0,0.0,0,0,0.0,0,0.0,0.0,0,0.0,0,0.0,0.0,0.0,0.0,900.0,24.0,20,0,0.0,20,0.0,900.0,1.0,48,500.0,0.5,0,0.0,0,,,10.0,3,30,0.0,0.0,1,115.65,0.05,,,,,,,,,,B2/L21,,,,Pm-3m/Fm-3m,,,,,,,,L10,,,,,P4/mmm,Modulations,,,,,,-22.65,-15.45,-13.74,-5.31,-0.64,1.51,15.25,24.16,,,2.3,1.55,,-8.46,6.06,,,,,,,,,,,,,,,,99.25,94.07,-24.07,9.9,-13.86,59.85,-13.2,109.15,9.14,103.68,-8.51,5.45,-0.21,75.25,0.68,99.52,10.23,104.39,10.86,9.19,13.76,-15.2,128.86,
32,"Salas, Karaman",,,,,,,,,,Internal,2016Q PC In13.5 FC,0.0,0.0,0.0,0.0,0,0.0,5.04,0.0,0.0,0,0.0,0.0,0.0,0.0,13.71,0.0,36.09,0.0,0.0,0.0,45.16,0,0.0,0.0,0.0,0.0,0,0,0.0,0,0.0,0.0,0,0.0,0,0.0,0.0,0.0,0.0,900.0,24.0,20,0,0.0,20,0.0,900.0,1.0,24,400.0,0.25,0,0.0,0,,,10.0,3,30,0.0,0.0,1,123.89,0.05,,,,,,,,,,B2/L21,,,,Pm-3m/Fm-3m,,,,,,,,L10,,,,,P4/mmm,Modulations,,,,,,-54.27,-44.83,-42.49,-31.93,-25.94,-21.88,20.61,32.39,,,2.17,1.58,,-8.81,7.01,,,,,,,,,,,,,,,,78.82,78.62,-61.59,8.44,-41.23,71.29,-39.05,87.26,3.5,86.2,-38.72,7.25,-26.3,62.15,-24.13,85.87,5.39,85.5,22.54,14.59,14.93,-10.71,162.94,
34,"Salas, Karaman",,,,,,,,,,Internal,2016Q PC In13.5 FC,0.0,0.0,0.0,0.0,0,0.0,5.04,0.0,0.0,0,0.0,0.0,0.0,0.0,13.71,0.0,36.09,0.0,0.0,0.0,45.16,0,0.0,0.0,0.0,0.0,0,0,0.0,0,0.0,0.0,0,0.0,0,0.0,0.0,0.0,0.0,900.0,24.0,20,0,0.0,20,0.0,900.0,1.0,24,400.0,3.0,0,0.0,0,,,10.0,3,30,0.0,0.0,1,123.79,0.05,,,,,,,,,,B2/L21,,,,Pm-3m/Fm-3m,,,,,,,,L10,,,,,P4/mmm,Modulations,,,,,,-49.89,-43.6,-38.94,-29.84,-23.71,-19.85,19.09,30.04,,,2.42,1.59,,-9.71,6.96,,,,,,,,,,,,,,,,83.43,80.72,-62.3,7.71,-42.34,59.29,-39.27,91.14,3.62,90.64,-35.28,8.09,-25.32,56.27,-23.17,88.81,6.66,87.76,23.03,12.11,16.56,-10.99,163.05,
36,"Salas, Karaman",,,,,,,,,,Internal,2016Q PC In13.7 WQ,0.0,0.0,0.0,0.0,0,0.0,5.01,0.0,0.0,0,0.0,0.0,0.0,0.0,13.98,0.0,36.09,0.0,0.0,0.0,44.97,0,0.0,0.0,0.0,0.0,0,0,0.0,0,0.0,0.0,0,0.0,0,0.0,0.0,0.0,0.0,20.0,0.0,20,0,0.0,20,0.0,900.0,24.0,0,500.0,72.0,0,0.0,0,,,10.0,3,30,0.0,0.0,1,115.29,0.05,,,,,,,,,,B2/L21,,,,Pm-3m/Fm-3m,,,,,,,,L10,,,,,P4/mmm,Modulations,,,,,,-54.68,-45.6,-43.76,-31.97,-25.2,-23.39,20.37,31.29,,,2.53,1.71,,-10.28,7.62,,,,,,,,,,,,,,,,55.2,55.78,-76.57,12.89,-50.83,53.2,-46.8,68.09,1.85,58.94,-40.75,12.04,-28.7,52.29,-26.51,67.82,3.92,59.39,29.77,14.24,21.21,-16.1,162.08,
38,"Salas, Karaman",,,,,,,,,,Internal,2016Q PC In13.6 FC,0.0,0.0,0.0,0.0,0,0.0,5.0,0.0,0.0,0,0.0,0.0,0.0,0.0,13.78,0.0,36.09,0.0,0.0,0.0,45.14,0,0.0,0.0,0.0,0.0,0,0,0.0,0,0.0,0.0,0,0.0,0,0.0,0.0,0.0,0.0,900.0,24.0,20,0,0.0,20,0.0,900.0,1.0,48,500.0,0.25,0,0.0,0,,,10.0,3,30,0.0,0.0,1,116.4,0.05,,,,,,,,,,B2/L21,,,,Pm-3m/Fm-3m,,,,,,,,L10,,,,,P4/mmm,Modulations,,,,,,-19.56,-14.4,-13.28,-6.16,-2.42,-0.54,12.74,19.02,,,2.32,1.75,,-8.6,6.79,,,,,,,,,,,,,,,,91.69,95.09,-18.02,9.66,-15.19,40.89,-13.81,101.35,21.79,97.32,-7.07,5.93,-1.71,64.92,-0.95,101.02,15.52,100.3,4.21,6.13,13.17,-15.48,130.2,
40,"Salas, Karaman",,,,,,,,,,Internal,2016Q PC In13.3 WQ,0.0,0.0,0.0,0.0,0,0.0,5.05,0.0,0.0,0,0.0,0.0,0.0,0.0,13.55,0.0,36.42,0.0,0.0,0.0,44.97,0,0.0,0.0,0.0,0.0,0,0,0.0,0,0.0,0.0,0,0.0,0,0.0,0.0,0.0,0.0,20.0,0.0,20,0,0.0,20,0.0,900.0,24.0,0,900.0,1.0,24,0.0,0,,,10.0,3,30,0.0,0.0,1,129.87,0.05,,,,,,,,,,B2/L21,6.01,,,Pm-3m/Fm-3m,,,,,,,,L10,,,,,P4/mmm,Modulations,,,,,,-43.08,-31.63,-29.8,-19.07,-11.89,-9.21,20.59,33.87,,,2.41,1.86,,-9.27,7.83,,,,,,,,,,,,,,,,65.07,66.99,-54.46,12,-37.03,50.43,-31.87,77.08,2.88,70.97,-29.94,10.36,-14.56,57.69,-12.35,77.35,3.81,72.27,22.59,17.6,21,-11.33,161.74,
42,"Salas, Karaman",,,,,,,,,,Internal,2016Q PC In13.6 FC,0.0,0.0,0.0,0.0,0,0.0,5.0,0.0,0.0,0,0.0,0.0,0.0,0.0,13.78,0.0,36.09,0.0,0.0,0.0,45.14,0,0.0,0.0,0.0,0.0,0,0,0.0,0,0.0,0.0,0,0.0,0,0.0,0.0,0.0,0.0,900.0,24.0,20,0,0.0,20,0.0,900.0,1.0,48,450.0,0.25,0,0.0,0,,,10.0,3,30,0.0,0.0,1,120.72,0.05,,,,,,,,,,B2/L21,,,,Pm-3m/Fm-3m,,,,,,,,L10,,,,,P4/mmm,Modulations,,,,,,-42.87,-32.25,-32.22,-22.11,-16.37,-13.42,18.8,29.45,,,2.89,1.94,,-11.28,8.16,,,,,,,,,,,,,,,,74.14,76.27,-44.82,10.78,-34.49,50.85,-32.09,84.92,5.83,81.29,-27.76,7.43,-18.54,58.84,-17.19,83.69,7.22,84,12.73,10.56,15.42,-11.52,152.81,
44,"Salas, Karaman",,,,,,,,,,Internal,2016Q PC In13.5 WQ,0.0,0.0,0.0,0.0,0,0.0,5.04,0.0,0.0,0,0.0,0.0,0.0,0.0,13.71,0.0,36.09,0.0,0.0,0.0,45.16,0,0.0,0.0,0.0,0.0,0,0,0.0,0,0.0,0.0,0,0.0,0,0.0,0.0,0.0,0.0,20.0,0.0,20,0,0.0,20,0.0,900.0,24.0,0,500.0,0.5,0,0.0,0,,,10.0,3,30,0.0,0.0,1,116.28,0.05,,,,,,,,,,B2/L21,,,,Pm-3m/Fm-3m,,,,,,,,L10,,,,,P4/mmm,Modulations,,,,,,-45.68,-42.18,-37.62,-29.13,-24.87,-18.23,19.39,27.45,,,2.86,1.98,,-11.48,8.55,,,,,,,,,,,,,,,,56.18,57.69,-56.68,9.8,-41.79,43.04,-36.85,65.98,2.83,61.69,-35.38,8.61,-24.44,46.67,-21.33,66.29,4.11,62.43,19.83,14.05,16.43,-12.52,153.14,
46,"Salas, Karaman",,,,,,,,,,Internal,2016Q PC In13.7 WQ,0.0,0.0,0.0,0.0,0,0.0,5.01,0.0,0.0,0,0.0,0.0,0.0,0.0,13.98,0.0,36.09,0.0,0.0,0.0,44.97,0,0.0,0.0,0.0,0.0,0,0,0.0,0,0.0,0.0,0,0.0,0,0.0,0.0,0.0,0.0,20.0,0.0,20,0,0.0,20,0.0,900.0,24.0,0,500.0,3.0,0,0.0,0,,,10.0,3,30,0.0,0.0,1,114.44,0.05,,,,,,,,,,B2/L21,,,,Pm-3m/Fm-3m,,,,,,,,L10,,,,,P4/mmm,Modulations,,,,,,-44.23,-37.17,-36.32,-25.51,-20.57,-17.33,18.99,26.9,,,2.9,2.01,,-11.5,8.57,,,,,,,,,,,,,,,,67.65,70.71,-50.52,11.58,-38.27,60.03,-37.04,79.24,5.02,74.38,-29.94,8.17,-20.42,59.81,-19.05,78.88,6.49,77.93,13.48,10.89,17.92,-13.11,151.48,
48,"Salas, Karaman",,,,,,,,,,Internal,2016Q PC In13.7 WQ,0.0,0.0,0.0,0.0,0,0.0,5.01,0.0,0.0,0,0.0,0.0,0.0,0.0,13.98,0.0,36.09,0.0,0.0,0.0,44.97,0,0.0,0.0,0.0,0.0,0,0,0.0,0,0.0,0.0,0,0.0,0,0.0,0.0,0.0,0.0,20.0,0.0,20,0,0.0,20,0.0,900.0,24.0,0,500.0,24.0,0,0.0,0,,,10.0,3,30,0.0,0.0,1,114.6,0.05,,,,,,,,,,B2/L21,,,,Pm-3m/Fm-3m,,,,,,,,L10,,,,,P4/mmm,Modulations,,,,,,-44.76,-36.46,-35.54,-25.54,-19.35,-17.73,17.81,27.03,,,2.97,2.03,,-11.76,8.67,,,,,,,,,,,,,,,,76.94,77.97,-47.46,11.48,-38.58,61.05,-37.46,88.42,7.7,81.49,-28.7,7.96,-20.31,63.72,-19.47,85.93,8.44,84.55,10,9.24,18.13,-12.07,152.06,
50,"Salas, Karaman",,,,,,,,,,Internal,2016Q PC In13.6 WQ,0.0,0.0,0.0,0.0,0,0.0,5.0,0.0,0.0,0,0.0,0.0,0.0,0.0,13.78,0.0,36.09,0.0,0.0,0.0,45.14,0,0.0,0.0,0.0,0.0,0,0,0.0,0,0.0,0.0,0,0.0,0,0.0,0.0,0.0,0.0,20.0,0.0,20,0,0.0,20,0.0,900.0,24.0,0,450.0,72.0,0,0.0,0,,,10.0,3,30,0.0,0.0,1,121.26,0.05,,,,,,,,,,B2/L21,,,,Pm-3m/Fm-3m,,,,,,,,L10,,,,,P4/mmm,Modulations,,,,,,-36.24,-29.61,-21.42,-18.23,-14.19,-9.08,12.34,27.16,,,2.64,2.12,,-10.2,8.69,,,,,,,,,,,,,,,,46.37,47.63,-44.53,8.64,-30,41.03,-24.88,55.01,2.36,49.32,-24.41,6.99,-15.67,33.48,-11.51,54.62,3.69,51.02,19.65,12.89,13.85,-15.59,146.15,
52,"Salas, Karaman",,,,,,,,,,Internal,2016Q PC In13.6 FC,0.0,0.0,0.0,0.0,0,0.0,5.0,0.0,0.0,0,0.0,0.0,0.0,0.0,13.78,0.0,36.09,0.0,0.0,0.0,45.14,0,0.0,0.0,0.0,0.0,0,0,0.0,0,0.0,0.0,0,0.0,0,0.0,0.0,0.0,0.0,900.0,24.0,20,0,0.0,20,0.0,900.0,1.0,48,450.0,3.0,0,0.0,0,,,10.0,3,30,0.0,0.0,1,120.74,0.05,,,,,,,,,,B2/L21,,,,Pm-3m/Fm-3m,,,,,,,,L10,,,,,P4/mmm,Modulations,,,,,,-42.73,-36.51,-35.79,-21.44,-16.67,-13.56,22.23,29.17,,,2.99,2.17,,-11.69,9.23,,,,,,,,,,,,,,,,70.77,73.46,-46.51,9.45,-35.94,56.58,-33.55,80.23,5.46,77.82,-27.62,7.68,-19.64,57.65,-17.92,81.14,7.58,79.62,12.96,9.7,15.96,-11.83,154.29,
54,"Salas, Karaman",,,,,,,,,,Internal,2016Q PC In13.3 WQ,0.0,0.0,0.0,0.0,0,0.0,5.05,0.0,0.0,0,0.0,0.0,0.0,0.0,13.55,0.0,36.42,0.0,0.0,0.0,44.97,0,0.0,0.0,0.0,0.0,0,0,0.0,0,0.0,0.0,0,0.0,0,0.0,0.0,0.0,0.0,20.0,0.0,20,0,0.0,20,0.0,900.0,24.0,0,400.0,0.5,0,0.0,0,,,10.0,3,30,0.0,0.0,1,122.85,0.05,,,,,,,,,,B2/L21,6.01,,,Pm-3m/Fm-3m,,,,,,,,L10,,,,,P4/mmm,Modulations,,,,,,-24.65,-19.39,-15.74,-7.83,-1.97,1.93,17.67,26.58,,,3.67,2.37,,-13.56,9.35,,,,,,,,,,,,,,,,83.79,80.31,-27.71,11.63,-19.89,76.19,-19.07,95.41,9.7,89.57,-10.01,9.16,-3.03,58.56,-0.83,89.46,8.75,88.2,8.64,9.18,17.55,-13.49,141.93,
56,"Salas, Karaman",,,,,,,,,,Internal,2016Q PC In13.5 FC,0.0,0.0,0.0,0.0,0,0.0,5.04,0.0,0.0,0,0.0,0.0,0.0,0.0,13.71,0.0,36.09,0.0,0.0,0.0,45.16,0,0.0,0.0,0.0,0.0,0,0,0.0,0,0.0,0.0,0,0.0,0,0.0,0.0,0.0,0.0,900.0,24.0,20,0,0.0,20,0.0,900.0,1.0,24,450.0,0.25,0,0.0,0,,,10.0,3,30,0.0,0.0,1,120,0.05,,,,,,,,,,B2/L21,,,,Pm-3m/Fm-3m,,,,,,,,L10,,,,,P4/mmm,Modulations,,,,,,-28.26,-20.16,-19.22,-10.81,-5.85,-1.99,17.23,26.27,,,3.49,2.46,,-13.08,9.82,,,,,,,,,,,,,,,,57.8,58.1,-38.92,5.11,-19.76,45.01,-18,62.91,2.76,62.63,-17.02,4.68,-6.92,40.82,-4.94,62.78,4.81,61.99,20.92,12.08,12.95,-14.04,138.01,
58,"Cho, Karaman",,,,,,,,,,Internal,,0.0,0.0,0.0,0.0,0,0.0,5.0,0.0,0.0,0,0.0,0.0,0.0,0.0,13.3,0.0,36.7,0.0,0.0,0.0,45.0,0,0.0,0.0,0.0,0.0,0,0,0.0,0,0.0,0.0,0,0.0,0,0.0,0.0,0.0,0.0,20.0,0.0,20,0,0.0,20,0.0,20.0,0.0,0,350.0,3.0,0,0.0,0,,,10.0,2,30,0.0,0.0,1,127.7,,,,,,,,,,,,,,,,,,,,,,,,,,,,,,,,,,,-34.35,-22.18,4.19,6.42,21.63,29.67,25.48,64.02,,,3.448,2.481,,,,,,,,,,,,,,,,,,,,,,,,,,,,,,,,,,,,,,,,,,
60,"Salas, Karaman",,,,,,,,,,Internal,2016Q PC In13.3 WQ,0.0,0.0,0.0,0.0,0,0.0,5.05,0.0,0.0,0,0.0,0.0,0.0,0.0,13.55,0.0,36.42,0.0,0.0,0.0,44.97,0,0.0,0.0,0.0,0.0,0,0,0.0,0,0.0,0.0,0,0.0,0,0.0,0.0,0.0,0.0,20.0,0.0,20,0,0.0,20,0.0,900.0,24.0,0,450.0,0.25,0,0.0,0,,,10.0,3,30,0.0,0.0,1,119.82,0.05,,,,,,,,,,B2/L21,6.01,,,Pm-3m/Fm-3m,,,,,,,,L10,,,,,P4/mmm,Modulations,,,,,,-12.92,-8.37,-7.13,0.3,3.53,8.13,15.26,21.05,,,3.7,2.56,,-13.36,9.72,,,,,,,,,,,,,,,,50.15,52.39,-21.91,7.57,-11.41,31.75,-7.7,57.72,3.53,53.46,-6.21,5.4,2.61,40.06,5.58,57.79,4.44,56.37,14.2,11.79,13.65,-19.04,127.53,
62,"Cho, Karaman",,,,,,,,,,Internal,,0.0,0.0,0.0,0.0,0,0.0,5.0,0.0,0.0,0,0.0,0.0,0.0,0.0,13.3,0.0,36.7,0.0,0.0,0.0,45.0,0,0.0,0.0,0.0,0.0,0,0,0.0,0,0.0,0.0,0,0.0,0,0.0,0.0,0.0,0.0,20.0,0.0,20,0,0.0,20,0.0,20.0,0.0,0,0.0,0.0,0,0.0,0,,,10.0,2,30,0.0,0.0,1,125.01,,,,,,,,,,,,,,,,,,,,,,,,,,,,,,,,,,,-22.92,-10.9,-10.72,-6.07,3.01,6.17,16.89,29.09,,,3.24,2.593,,,,,,,,,,,,,,,,,,,,,,,,,,,,,,,,,,,,,,,,,,
64,"Salas, Karaman",,,,,,,,,,Internal,2016Q PC In13.3 WQ,0.0,0.0,0.0,0.0,0,0.0,5.05,0.0,0.0,0,0.0,0.0,0.0,0.0,13.55,0.0,36.42,0.0,0.0,0.0,44.97,0,0.0,0.0,0.0,0.0,0,0,0.0,0,0.0,0.0,0,0.0,0,0.0,0.0,0.0,0.0,20.0,0.0,20,0,0.0,20,0.0,900.0,24.0,0,400.0,0.25,0,0.0,0,,,10.0,3,30,0.0,0.0,1,122.95,0.05,,,,,,,,,,B2/L21,6.01,,,Pm-3m/Fm-3m,,,,,,,,L10,,,,,P4/mmm,Modulations,,,,,,-22.25,-16.24,-11.2,-6.75,-1.48,4.92,16.12,27.17,,,3.91,2.61,,-14.37,10.17,,,,,,,,,,,,,,,,50.75,52.04,-35.01,8.44,-18.89,36.4,-12.66,59.19,2.27,55.96,-14.38,6.76,-2.14,39.66,1.31,58.8,3.32,57.02,22.34,15.68,15.36,-14.45,135.61,
66,"Salas, Karaman",,,,,,,,,,Internal,2016Q PC In13.5 FC,0.0,0.0,0.0,0.0,0,0.0,5.04,0.0,0.0,0,0.0,0.0,0.0,0.0,13.71,0.0,36.09,0.0,0.0,0.0,45.16,0,0.0,0.0,0.0,0.0,0,0,0.0,0,0.0,0.0,0,0.0,0,0.0,0.0,0.0,0.0,900.0,24.0,20,0,0.0,20,0.0,900.0,1.0,24,450.0,24.0,0,0.0,0,,,10.0,3,30,0.0,0.0,1,120.01,0.05,,,,,,,,,,B2/L21,,,,Pm-3m/Fm-3m,,,,,,,,L10,,,,,P4/mmm,Modulations,,,,,,-26.71,-20.02,-17.03,-8.55,-4.45,-0.83,16.2,25.88,,,3.53,2.69,,-13.14,10.67,,,,,,,,,,,,,,,,57.42,57.52,-39.56,4.98,-19.45,44.87,-17.08,62.4,2.55,62.48,-15.71,4.85,-5.02,47.3,-3.38,62.38,4.66,62.12,22.48,12.33,14.06,-14.05,137.09,
68,"Salas, Karaman",,,,,,,,,,Internal,2016Q PC In13.6 WQ,0.0,0.0,0.0,0.0,0,0.0,5.0,0.0,0.0,0,0.0,0.0,0.0,0.0,13.78,0.0,36.09,0.0,0.0,0.0,45.14,0,0.0,0.0,0.0,0.0,0,0,0.0,0,0.0,0.0,0,0.0,0,0.0,0.0,0.0,0.0,20.0,0.0,20,0,0.0,20,0.0,900.0,24.0,0,500.0,3.0,0,0.0,0,,,10.0,3,30,0.0,0.0,1,117.86,0.05,,,,,,,,,,B2/L21,,,,Pm-3m/Fm-3m,,,,,,,,L10,,,,,P4/mmm,Modulations,,,,,,-23.57,-17.13,-15.11,-8.38,-4.97,-1.21,13.9,22.36,,,3.92,2.81,,-14.61,11.04,,,,,,,,,,,,,,,,68.3,68.64,-23.59,7.66,-16.1,51.59,-14.13,75.96,7.22,73.37,-10.91,5.44,-4.93,47.27,-2.78,74.08,8.44,74.33,9.46,8.13,11.26,-13.34,131.99,
70,"Salas, Karaman",,,,,,,,,,Internal,2016Q PC In13.5 WQ,0.0,0.0,0.0,0.0,0,0.0,5.04,0.0,0.0,0,0.0,0.0,0.0,0.0,13.71,0.0,36.09,0.0,0.0,0.0,45.16,0,0.0,0.0,0.0,0.0,0,0,0.0,0,0.0,0.0,0,0.0,0,0.0,0.0,0.0,0.0,20.0,0.0,20,0,0.0,20,0.0,900.0,24.0,0,450.0,24.0,0,0.0,0,,,10.0,3,30,0.0,0.0,1,120.12,0.05,,,,,,,,,,B2/L21,,,,Pm-3m/Fm-3m,,,,,,,,L10,,,,,P4/mmm,Modulations,,,,,,-18.53,-13,-11.44,-3.32,0.01,3.05,14.49,21.58,,,3.96,2.93,,-14.52,11.34,,,,,,,,,,,,,,,,38.05,39.23,-26.32,5.24,-16.58,24.99,-12.58,43.29,2.77,41.05,-8.34,3.87,-1.12,27.39,1.07,43.1,4.17,43.63,13.74,9.41,14.56,-15.9,132.7,
72,"Salas, Karaman",,,,,,,,,,Internal,2016Q PC In13.6 WQ,0.0,0.0,0.0,0.0,0,0.0,5.0,0.0,0.0,0,0.0,0.0,0.0,0.0,13.78,0.0,36.09,0.0,0.0,0.0,45.14,0,0.0,0.0,0.0,0.0,0,0,0.0,0,0.0,0.0,0,0.0,0,0.0,0.0,0.0,0.0,20.0,0.0,20,0,0.0,20,0.0,900.0,24.0,0,500.0,72.0,0,0.0,0,,,10.0,3,30,0.0,0.0,1,116.92,0.05,,,,,,,,,,B2/L21,,,,Pm-3m/Fm-3m,,,,,,,,L10,,,,,P4/mmm,Modulations,,,,,,-18.77,-11.98,-10.76,-3.87,0.45,2.96,13.72,21.73,,,3.83,3.14,,-14.04,12.1,,,,,,,,,,,,,,,,84.11,84.48,-19.91,9.36,-13.01,62.45,-11.83,93.47,10.4,91.99,-6.88,6.55,-0.49,62.98,0.5,91.03,11.44,91.84,8.08,7.38,12.42,-14.38,128.75,
74,"Salas, Karaman",,,,,,,,,,Internal,2016Q PC In13.6 FC,0.0,0.0,0.0,0.0,0,0.0,5.0,0.0,0.0,0,0.0,0.0,0.0,0.0,13.78,0.0,36.09,0.0,0.0,0.0,45.14,0,0.0,0.0,0.0,0.0,0,0,0.0,0,0.0,0.0,0,0.0,0,0.0,0.0,0.0,0.0,900.0,24.0,20,0,0.0,20,0.0,900.0,1.0,48,500.0,72.0,0,0.0,0,,,10.0,3,30,0.0,0.0,1,116.25,0.05,,,,,,,,,,B2/L21,,,,Pm-3m/Fm-3m,,,,,,,,L10,,,,,P4/mmm,Modulations,,,,,,-18.16,-12.12,-10.85,-1.07,3.61,7.06,17.91,25.22,,,4.08,3.23,,-14.79,12.46,,,,,,,,,,,,,,,,86.21,86.75,-17.15,6.33,-9,67.51,-8.15,92.55,9.58,93.96,-4.77,4.53,2.09,62.9,2.91,91.28,11.29,92.04,9,7.68,11.07,-16,124.4,
76,"Salas, Karaman",,,,,,,,,,Internal,2016Q PC In13.5 WQ,0.0,0.0,0.0,0.0,0,0.0,5.04,0.0,0.0,0,0.0,0.0,0.0,0.0,13.71,0.0,36.09,0.0,0.0,0.0,45.16,0,0.0,0.0,0.0,0.0,0,0,0.0,0,0.0,0.0,0,0.0,0,0.0,0.0,0.0,0.0,20.0,0.0,20,0,0.0,20,0.0,900.0,24.0,0,500.0,72.0,0,0.0,0,,,10.0,3,30,0.0,0.0,1,116.32,0.05,,,,,,,,,,B2/L21,,,,Pm-3m/Fm-3m,,,,,,,,L10,,,,,P4/mmm,Modulations,,,,,,-12.65,-6.79,-1.6,3.68,7.54,10.76,12.36,23.41,,,3.85,3.28,,-13.72,12.3,,,,,,,,,,,,,,,,58.13,59.39,-16.36,10.06,-6.55,43.71,-3.56,68.19,4.54,61.59,0.13,8.09,6.62,41.93,9.32,67.48,6.46,62.97,12.8,9.19,13.02,-16.54,119.88,
78,"Salas, Karaman",,,,,,,,,,Internal,2016Q PC In13.7 WQ,0.0,0.0,0.0,0.0,0,0.0,5.01,0.0,0.0,0,0.0,0.0,0.0,0.0,13.98,0.0,36.09,0.0,0.0,0.0,44.97,0,0.0,0.0,0.0,0.0,0,0,0.0,0,0.0,0.0,0,0.0,0,0.0,0.0,0.0,0.0,20.0,0.0,20,0,0.0,20,0.0,900.0,24.0,0,600.0,72.0,0,0.0,0,,,10.0,3,30,0.0,0.0,1,108.9,0.05,,,,,,,,,,B2/L21,,,,Pm-3m/Fm-3m,,,,,,,,L10,,,,,P4/mmm,Modulations,,,,,,-22.43,-17.71,-8.81,-7.23,-4.72,3.33,12.14,25.76,,,4.13,3.49,,-15.27,13.6,,,,,,,,,,,,,,,,70.19,72.63,-24.17,8.04,-16.24,39.94,-8,78.23,4.34,78.08,-11.71,5.59,-5.12,36.49,1.99,78.22,5.3,80.1,16.18,13.7,10.55,-16.96,116.9,
80,"Salas, Karaman",,,,,,,,,,Internal,2016Q PC In13.7 WQ,0.0,0.0,0.0,0.0,0,0.0,5.01,0.0,0.0,0,0.0,0.0,0.0,0.0,13.98,0.0,36.09,0.0,0.0,0.0,44.97,0,0.0,0.0,0.0,0.0,0,0,0.0,0,0.0,0.0,0,0.0,0,0.0,0.0,0.0,0.0,20.0,0.0,20,0,0.0,20,0.0,900.0,24.0,0,600.0,3.0,0,0.0,0,,,10.0,3,30,0.0,0.0,1,107.94,0.05,,,,,,,,,,B2/L21,,,,Pm-3m/Fm-3m,,,,,,,,L10,,,,,P4/mmm,Modulations,,,,,,-23.24,-16.16,-14.19,-6.2,-1.49,2.1,16.29,25.34,,,4.44,3.58,,-16.37,14.02,,,,,,,,,,,,,,,,81.2,81.12,-22.92,8.02,-16.42,41.22,-9.58,89.23,6.08,88.94,-9.64,5.94,-4.31,42.12,2.01,87.06,6.97,89.55,13.35,11.64,11.85,-13.16,117.52,
82,"Salas, Karaman",,,,,,,,,,Internal,2016Q PC In13.3 WQ,0.0,0.0,0.0,0.0,0,0.0,5.05,0.0,0.0,0,0.0,0.0,0.0,0.0,13.55,0.0,36.42,0.0,0.0,0.0,44.97,0,0.0,0.0,0.0,0.0,0,0,0.0,0,0.0,0.0,0,0.0,0,0.0,0.0,0.0,0.0,20.0,0.0,20,0,0.0,20,0.0,900.0,24.0,0,500.0,0.25,0,0.0,0,,,10.0,3,30,0.0,0.0,1,118.05,0.05,,,,,,,,,,B2/L21,6.01,,,Pm-3m/Fm-3m,,,,,,,,L10,,,,,P4/mmm,Modulations,,,,,,-9.05,-2.7,-0.68,5.49,9.94,13.67,14.35,22.72,,,4.41,3.74,,-15.6,13.9,,,,,,,,,,,,,,,,45.46,46.66,-11.19,5.58,-1.63,35.06,0.14,51.04,4.01,47.99,1.77,3.98,10.24,32.93,12.36,50.64,4.41,49.59,11.32,10.59,12.05,-18.6,117.91,
84,"Salas, Karaman",,,,,,,,,,Internal,2016Q PC In13.7 WQ,0.0,0.0,0.0,0.0,0,0.0,5.01,0.0,0.0,0,0.0,0.0,0.0,0.0,13.98,0.0,36.09,0.0,0.0,0.0,44.97,0,0.0,0.0,0.0,0.0,0,0,0.0,0,0.0,0.0,0,0.0,0,0.0,0.0,0.0,0.0,20.0,0.0,20,0,0.0,20,0.0,900.0,24.0,0,600.0,24.0,0,0.0,0,,,10.0,3,30,0.0,0.0,1,108.25,0.05,,,,,,,,,,B2/L21,,,,Pm-3m/Fm-3m,,,,,,,,L10,,,,,P4/mmm,Modulations,,,,,,-21.67,-15,-7.55,-5.89,-2.28,3.99,11.54,25.66,,,4.49,3.79,,-16.54,14.7,,,,,,,,,,,,,,,,76.54,80.6,-21.79,9.6,-13.77,45.65,-7.76,86.14,5.46,84.08,-8.96,6.67,-2.09,44.29,2.72,87.27,6.9,88.22,14.02,11.68,11.08,-12.67,116.01,
86,"Cho, Karaman",,,,,,,,,,Internal,,0.0,0.0,0.0,0.0,0,0.0,5.0,0.0,0.0,0,0.0,0.0,0.0,0.0,13.3,0.0,36.7,0.0,0.0,0.0,45.0,0,0.0,0.0,0.0,0.0,0,0,0.0,0,0.0,0.0,0,0.0,0,0.0,0.0,0.0,0.0,20.0,0.0,20,0,0.0,20,0.0,20.0,0.0,0,400.0,3.0,0,0.0,0,,,10.0,2,30,0.0,0.0,1,125.09,,,,,,,,,,,,,,,,,,,,,,,,,,,,,,,,,,,-14.4,5.77,13.96,21.33,35.3,44.43,30.47,58.83,,,3.964,3.828,,,,,,,,,,,,,,,,,,,,,,,,,,,,,,,,,,,,,,,,,,
88,"Cho, Karaman",,,,,,,,,,Internal,,0.0,0.0,0.0,0.0,0,0.0,5.0,0.0,0.0,0,0.0,0.0,0.0,0.0,13.3,0.0,36.7,0.0,0.0,0.0,45.0,0,0.0,0.0,0.0,0.0,0,0,0.0,0,0.0,0.0,0,0.0,0,0.0,0.0,0.0,0.0,20.0,0.0,20,0,0.0,20,0.0,20.0,0.0,0,550.0,3.0,0,0.0,0,,,10.0,2,30,0.0,0.0,1,115.83,,,,,,,,,,,,,,,,,,,,,,,,,,,,,,,,,,,20.79,26.44,26.75,29.85,36.28,39.77,13.02,18.98,,,4.419,3.999,,,,,,,,,,,,,,,,,,,,,,,,,,,,,,,,,,,,,,,,,,
90,"Cho, Karaman",,,,,,,,,,Internal,,0.0,0.0,0.0,0.0,0,0.0,5.0,0.0,0.0,0,0.0,0.0,0.0,0.0,13.3,0.0,36.7,0.0,0.0,0.0,45.0,0,0.0,0.0,0.0,0.0,0,0,0.0,0,0.0,0.0,0,0.0,0,0.0,0.0,0.0,0.0,20.0,0.0,20,0,0.0,20,0.0,20.0,0.0,0,450.0,3.0,0,0.0,0,,,10.0,2,30,0.0,0.0,1,123.93,,,,,,,,,,,,,,,,,,,,,,,,,,,,,,,,,,,-7.36,13.24,21.45,28.02,42.69,52.09,30.64,59.45,,,4.618,4.048,,,,,,,,,,,,,,,,,,,,,,,,,,,,,,,,,,,,,,,,,,
92,"Salas, Karaman",,,,,,,,,,Internal,2016Q PC In13.7 WQ,0.0,0.0,0.0,0.0,0,0.0,5.01,0.0,0.0,0,0.0,0.0,0.0,0.0,13.98,0.0,36.09,0.0,0.0,0.0,44.97,0,0.0,0.0,0.0,0.0,0,0,0.0,0,0.0,0.0,0,0.0,0,0.0,0.0,0.0,0.0,20.0,0.0,20,0,0.0,20,0.0,900.0,24.0,0,600.0,0.5,0,0.0,0,,,10.0,3,30,0.0,0.0,1,107.47,0.05,,,,,,,,,,B2/L21,,,,Pm-3m/Fm-3m,,,,,,,,L10,,,,,P4/mmm,Modulations,,,,,,-23.74,-17.49,-3.44,-5.18,-0.68,10.75,14.19,34.49,,,5.14,4.08,,-18.75,15.88,,,,,,,,,,,,,,,,76.67,76.79,-18.56,7.71,-14.09,41.35,-4.64,84.38,5.51,82.47,-5.99,5.25,-0.85,41.03,5.77,82.05,6.53,84.24,13.92,11.76,11.82,-14.85,112.11,
94,"Salas, Karaman",,,,,,,,,,Internal,2016Q PC In13.7 WQ,0.0,0.0,0.0,0.0,0,0.0,5.01,0.0,0.0,0,0.0,0.0,0.0,0.0,13.98,0.0,36.09,0.0,0.0,0.0,44.97,0,0.0,0.0,0.0,0.0,0,0,0.0,0,0.0,0.0,0,0.0,0,0.0,0.0,0.0,0.0,20.0,0.0,20,0,0.0,20,0.0,900.0,24.0,0,600.0,0.25,0,0.0,0,,,10.0,3,30,0.0,0.0,1,105.76,0.05,,,,,,,,,,B2/L21,,,,Pm-3m/Fm-3m,,,,,,,,L10,,,,,P4/mmm,Modulations,,,,,,-15.75,-9.75,0.04,-0.96,3.2,12.42,12.38,28.17,,,5.75,4.44,,-20.67,16.81,,,,,,,,,,,,,,,,79.64,75.49,-14.6,5.17,-4.9,50.22,1.11,84.81,5.07,84.16,-0.79,4.95,4.01,37.62,11.18,80.45,6.31,82.19,15.71,11.97,9.49,-15.4,104.65,
96,"Salas, Karaman",,,,,,,,,,Internal,2016Q PC In13.5 WQ,0.0,0.0,0.0,0.0,0,0.0,5.04,0.0,0.0,0,0.0,0.0,0.0,0.0,13.71,0.0,36.09,0.0,0.0,0.0,45.16,0,0.0,0.0,0.0,0.0,0,0,0.0,0,0.0,0.0,0,0.0,0,0.0,0.0,0.0,0.0,20.0,0.0,20,0,0.0,20,0.0,900.0,24.0,0,600.0,0.5,0,0.0,0,,,10.0,3,30,0.0,0.0,1,108.56,0.05,,,,,,,,,,B2/L21,,,,Pm-3m/Fm-3m,,,,,,,,L10,,,,,P4/mmm,Modulations,,,,,,7.06,10.55,18.5,21.76,23.84,30.94,12.44,23.88,,,5.52,4.66,,-18.49,16.38,,,,,,,,,,,,,,,,51.63,52.48,5.86,5.37,12.26,27.33,22.9,57,3.03,55.42,19.35,3.95,24.85,31.44,31.96,56.43,4.16,56.93,17.05,12.61,10.82,-11.47,85.66,
98,"Salas, Karaman",,,,,,,,,,Internal,2016Q PC In13.6 WQ,0.0,0.0,0.0,0.0,0,0.0,5.0,0.0,0.0,0,0.0,0.0,0.0,0.0,13.78,0.0,36.09,0.0,0.0,0.0,45.14,0,0.0,0.0,0.0,0.0,0,0,0.0,0,0.0,0.0,0,0.0,0,0.0,0.0,0.0,0.0,20.0,0.0,20,0,0.0,20,0.0,900.0,24.0,0,600.0,0.25,0,0.0,0,,,10.0,3,30,0.0,0.0,1,108.97,0.05,,,,,,,,,,B2/L21,,,,Pm-3m/Fm-3m,,,,,,,,L10,,,,,P4/mmm,Modulations,,,,,,1.61,6.79,7.05,13.04,15.95,19.29,12.24,17.68,,,5.84,4.8,,-20.21,17.28,,,,,,,,,,,,,,,,55.97,56.35,-1.39,4.42,6.55,38.25,8.14,60.39,5.87,58.76,11,3.87,15.97,38.75,17.84,60.22,8.23,60.45,9.53,6.85,9.56,-23.38,100.83,
100,"Salas, Karaman",,,,,,,,,,Internal,2016Q PC In13.6 WQ,0.0,0.0,0.0,0.0,0,0.0,5.0,0.0,0.0,0,0.0,0.0,0.0,0.0,13.78,0.0,36.09,0.0,0.0,0.0,45.14,0,0.0,0.0,0.0,0.0,0,0,0.0,0,0.0,0.0,0,0.0,0,0.0,0.0,0.0,0.0,20.0,0.0,20,0,0.0,20,0.0,900.0,24.0,0,600.0,3.0,0,0.0,0,,,10.0,3,30,0.0,0.0,1,110.12,0.05,,,,,,,,,,B2/L21,,,,Pm-3m/Fm-3m,,,,,,,,L10,,,,,P4/mmm,Modulations,,,,,,-1.17,2.73,7.71,11.45,13.95,18.79,11.08,19.96,,,5.81,5.06,,-20.2,18.31,,,,,,,,,,,,,,,,66.3,68.46,-3.78,6.79,5.02,42.41,10.45,73.09,4.66,72.56,6.49,4.85,12.88,37.53,18.63,73.3,5.64,74.78,14.23,12.14,8.02,-16.76,99.67,
102,"Cho, Karaman",,,,,,,,,,Internal,,0.0,0.0,0.0,0.0,0,0.0,5.0,0.0,0.0,0,0.0,0.0,0.0,0.0,13.3,0.0,36.7,0.0,0.0,0.0,45.0,0,0.0,0.0,0.0,0.0,0,0,0.0,0,0.0,0.0,0,0.0,0,0.0,0.0,0.0,0.0,20.0,0.0,20,0,0.0,20,0.0,20.0,0.0,0,650.0,3.0,0,0.0,0,,,10.0,2,30,0.0,0.0,1,117.57,,,,,,,,,,,,,,,,,,,,,,,,,,,,,,,,,,,14.58,22.19,24.94,30.27,38.08,41.51,16.57,26.93,,,6.191,5.309,,,,,,,,,,,,,,,,,,,,,,,,,,,,,,,,,,,,,,,,,,
104,"Cho, Karaman",,,,,,,,,,Internal,,0.0,0.0,0.0,0.0,0,0.0,5.0,0.0,0.0,0,0.0,0.0,0.0,0.0,13.3,0.0,36.7,0.0,0.0,0.0,45.0,0,0.0,0.0,0.0,0.0,0,0,0.0,0,0.0,0.0,0,0.0,0,0.0,0.0,0.0,0.0,20.0,0.0,20,0,0.0,20,0.0,20.0,0.0,0,550.0,3.0,0,0.0,0,,,10.0,2,30,0.0,0.0,1,118.06,,,,,,,,,,,,,,,,,,,,,,,,,,,,,,,,,,,13.87,22.19,24.95,30.68,38.08,41.83,16.88,27.96,,,6.168,5.48,,,,,,,,,,,,,,,,,,,,,,,,,,,,,,,,,,,,,,,,,,
106,"Salas, Karaman",,,,,,,,,,Internal,2016Q PC In13.3 WQ,0.0,0.0,0.0,0.0,0,0.0,5.05,0.0,0.0,0,0.0,0.0,0.0,0.0,13.55,0.0,36.42,0.0,0.0,0.0,44.97,0,0.0,0.0,0.0,0.0,0,0,0.0,0,0.0,0.0,0,0.0,0,0.0,0.0,0.0,0.0,20.0,0.0,20,0,0.0,20,0.0,900.0,24.0,0,450.0,72.0,0,0.0,0,,,10.0,3,30,0.0,0.0,1,121.12,0.05,,,,,,,,,,B2/L21,6.01,,,Pm-3m/Fm-3m,,,,,,,,L10,,,,,P4/mmm,Modulations,,,,,,20.2,23.47,28.13,33.44,36.52,39.39,11.26,19.19,,,5.78,5.52,,-18.68,18.59,,,,,,,,,,,,,,,,55.76,54.99,18.31,5.29,24.9,33.73,28.09,61.05,5.71,60.96,30.82,4.5,36.29,41.33,37.77,59.49,7.91,60.7,9.77,6.96,10.54,-21.96,93.04,
108,"Salas, Karaman",,,,,,,,,,Internal,2016Q PC In13.5 WQ,0.0,0.0,0.0,0.0,0,0.0,5.04,0.0,0.0,0,0.0,0.0,0.0,0.0,13.71,0.0,36.09,0.0,0.0,0.0,45.16,0,0.0,0.0,0.0,0.0,0,0,0.0,0,0.0,0.0,0,0.0,0,0.0,0.0,0.0,0.0,20.0,0.0,20,0,0.0,20,0.0,900.0,24.0,0,600.0,0.25,0,0.0,0,,,10.0,3,30,0.0,0.0,1,105.74,0.05,,,,,,,,,,B2/L21,,,,Pm-3m/Fm-3m,,,,,,,,L10,,,,,P4/mmm,Modulations,,,,,,7.88,13.38,20.68,24.12,26.43,33.33,12.65,25.45,,,6.97,5.97,,-23.16,20.82,,,,,,,,,,,,,,,,44.93,45.79,8.45,4.77,14.82,24.3,21.69,49.69,3.39,48.56,22.43,3.25,30.41,35.85,32.88,49.04,4.38,50.24,13.23,10.45,13.39,-22.87,84.05,
110,"Salas, Karaman",,,,,,,,,,Internal,2016Q PC In13.3 WQ,0.0,0.0,0.0,0.0,0,0.0,5.05,0.0,0.0,0,0.0,0.0,0.0,0.0,13.55,0.0,36.42,0.0,0.0,0.0,44.97,0,0.0,0.0,0.0,0.0,0,0,0.0,0,0.0,0.0,0,0.0,0,0.0,0.0,0.0,0.0,20.0,0.0,20,0,0.0,20,0.0,900.0,24.0,0,500.0,72.0,0,0.0,0,,,10.0,3,30,0.0,0.0,1,116.56,0.05,,,,,,,,,,B2/L21,6.01,,,Pm-3m/Fm-3m,,,,,,,,L10,,,,,P4/mmm,Modulations,,,,,,27.93,33.72,35.03,38.65,42.1,45.21,10.18,17.28,,,6.58,6.11,,-20.89,20.02,,,,,,,,,,,,,,,,73.43,69.24,27.16,3.75,34.1,43.84,36.78,77.18,7.64,82.71,37.53,3.44,43.97,42.96,46.64,72.69,7.6,77.43,9.62,9.11,9.87,-16.98,79.78,
112,"Salas, Karaman",,,,,,,,,,Internal,2016Q PC In13.3 WQ,0.0,0.0,0.0,0.0,0,0.0,5.05,0.0,0.0,0,0.0,0.0,0.0,0.0,13.55,0.0,36.42,0.0,0.0,0.0,44.97,0,0.0,0.0,0.0,0.0,0,0,0.0,0,0.0,0.0,0,0.0,0,0.0,0.0,0.0,0.0,20.0,0.0,20,0,0.0,20,0.0,900.0,24.0,0,600.0,0.5,0,0.0,0,,,10.0,3,30,0.0,0.0,1,107.35,0.05,,,,,,,,,,B2/L21,6.01,,,Pm-3m/Fm-3m,,,,,,,,L10,,,,,P4/mmm,Modulations,,,,,,39.47,43.83,44.8,49.54,52.24,54.66,9.86,15.19,,,8.99,8.04,,-27.66,25.46,,,,,,,,,,,,,,,,,,,,,,,,,,,,,,,,,,,,,,,
114,"Can, Karaman",,,,,,,,,,Internal,,0.0,0.0,0.0,0.0,0,0.0,0.0,0.0,0.0,0,0.0,0.0,0.0,0.0,0.0,0.0,0.0,0.0,0.0,0.0,24.5,0,25.0,0.0,0.0,0.0,0,0,0.0,0,0.0,0.0,0,50.5,0,0.0,0.0,0.0,0.0,20.0,0.0,20,0,0.0,20,0.0,20.0,0.0,0,20.0,0.0,0,0.0,0,50,220,10.0,2,30,0.0,0.0,1,,,,,,,,,,,,,,,,,,,,,,,,,,,,,,,,,,,,118.3,133.9,147.2,147.4,158.8,167.7,20.5,49.4,,,14.163,14.142,,,,,,,,,,,,,,,,,,,,,,,,,,,,,,,,,,,,,,,,,,
116,"Joel, Karaman",,,,,,,305 Series,,,Internal,,0.0,0.0,0.0,0.0,0,0.0,0.0,0.0,0.0,0,0.0,0.0,0.0,19.4,0.0,0.0,0.0,0.0,0.0,0.0,50.8,0,0.0,0.0,0.0,0.0,0,0,0.0,0,0.0,0.0,0,29.8,0,0.0,0.0,0.0,0.0,1050.0,72.0,20,0,0.0,92020,185.0,20.0,0.0,0,900.0,1.0,0,0.0,0,,,10.0,3,30,0.0,0.0,1,,,,,,,,,,,,,,,,,,,,,,,,,,,,,,,,,,,,142.2,156.9,163.4,180.6,188.4,192.7,29.3,50.5,,,15.3,14.9,,,,,,,,,,,,,,,,,,,,,,,,,,,,,,,,,,,,,,,,,,
118,"Can, Karaman",,,,,,,,,,Internal,,0.0,0.0,0.0,0.0,0,0.0,0.0,0.0,0.0,0,0.0,0.0,0.0,0.0,0.0,0.0,0.0,0.0,0.0,0.0,24.5,0,25.0,0.0,0.0,0.0,0,0,0.0,0,0.0,0.5,0,50.0,0,0.0,0.0,0.0,0.0,20.0,0.0,20,0,0.0,92020,700.0,20.0,0.0,0,20.0,0.0,0,0.0,0,95,260,10.0,2,30,0.0,0.0,1,,,,,,,,,,,,,,,,,,,,,,,,,,,,,,,,,,,,149.8,156.4,161.6,169.4,175.8,179,17.4,29.2,,,19.443,19.452,,,,,,,,,,,,,,,,,,,,,,,,,,,,,,,,,,,,,,,,,,
120,"Can, Karaman",,,,,,,,,44,Internal,Sample failed at 400MPa,0.0,0.0,0.0,0.0,0,0.0,0.0,0.0,0.0,0,0.0,0.0,0.0,0.0,0.0,0.0,0.0,0.0,0.0,0.0,25.0,0,25.0,0.0,0.0,0.0,0,0,0.5,0,0.0,0.0,0,49.5,0,0.0,0.0,0.0,0.0,20.0,0.0,20,0,0.0,92020,700.0,20.0,0.0,0,20.0,0.0,0,400.0,0,40,200,10.0,15,30,0.0,0.0,1,,,,,,,,,,,,,,,,,,,,,,,,,,,,,,,,,,,,,,,,,,,,,,,,,,,,,,1,,,,,,,,,,,,,,,,,,,,,,,,,,,,,,,,,,,
122,"Can, Karaman",,,,,,,,,122,Internal,,0.0,0.0,0.0,0.0,0,0.0,0.0,0.0,0.0,0,0.0,0.0,0.0,0.0,0.0,0.0,0.0,0.0,0.0,0.0,24.5,0,25.0,0.0,0.0,0.0,0,0,0.0,0,0.0,1.0,0,49.5,0,0.0,0.0,0.0,0.0,20.0,0.0,20,0,0.0,92020,700.0,20.0,0.0,0,20.0,0.0,0,350.0,0,100,280,10.0,8,30,0.0,0.0,1,,,,,,,,,,,,,,,,,,,,,,,,,,,,,,,,,,,,,,,,,,,,,,,,,,,,,,1,,,,,,,,,,,,,,,,,,,,,,,,,,,,,,,,,,,
124,"Can, Karaman",,,,,,,,,39,Internal,,0.0,0.0,0.0,0.0,0,0.0,0.0,0.0,0.0,0,0.0,0.0,0.0,0.0,0.0,0.0,0.0,0.0,0.0,0.0,27.0,0,25.0,0.0,0.0,0.0,0,0,0.0,0,0.0,0.0,0,48.0,0,0.0,0.0,0.0,0.0,20.0,0.0,20,0,0.0,92020,700.0,20.0,0.0,0,400.0,10.0,0,100.0,0,-60,110,10.0,2,30,0.0,0.0,1,,,,,,,,,,,,,,,,,,,,,,,,,,,,,,,,,,,,33.3,,54.7,68.8,,91.5,36.8,58.2,,,,,,,,,0.983,0.07,,,,,,,,,,,,,,,,,,,,,,,,,,,,,,,,,,,,
125,"Can, Karaman",,,,,,,,,39,Internal,,0.0,0.0,0.0,0.0,0,0.0,0.0,0.0,0.0,0,0.0,0.0,0.0,0.0,0.0,0.0,0.0,0.0,0.0,0.0,27.0,0,25.0,0.0,0.0,0.0,0,0,0.0,0,0.0,0.0,0,48.0,0,0.0,0.0,0.0,0.0,20.0,0.0,20,0,0.0,92020,700.0,20.0,0.0,0,400.0,10.0,0,150.0,0,-60,105,10.0,3,30,0.0,0.0,1,,,,,,,,,,,,,,,,,,,,,,,,,,,,,,,,,,,,38,,61.5,70.7,,98.3,36.8,60.3,,,,,,,,,1.33,,,,,,,,,,,,,,,,,,,,,,,,,,,,,,,,,,,,,
126,"Can, Karaman",,,,,,,,,94,Internal,"We did heat treatment to the as-extruded sample at 500C for 24 hours followed by water quenching, then ran the load bias test on the HT'ed sample.",0.0,0.0,0.0,0.0,0,0.0,0.0,0.0,0.0,0,0.0,0.0,0.0,0.0,0.0,0.0,0.0,0.0,0.0,0.0,24.5,0,25.0,0.0,0.0,0.0,0,0,3.0,0,0.0,0.0,0,47.5,0,0.0,0.0,0.0,0.0,20.0,0.0,20,0,0.0,92020,700.0,20.0,0.0,0,500.0,24.0,0,50.0,0,-20,140,10.0,2,30,0.0,0.0,1,,,,,,,,,,,,,,,,,,,,,,,,,,,,,,,,,,,,31.8,,44.8,51.2,,61.5,16.7,29.7,,,,,,,,,1.14,0,,,,,,,,,,,,,,,,,,,,,,,,,,,,,,,,,,,,
127,"Can, Karaman",,,,,,,,,92,Internal,,0.0,0.0,0.0,0.0,0,0.0,0.0,0.0,0.0,0,0.0,0.0,0.0,0.0,0.0,0.0,0.0,0.0,0.0,0.0,24.5,0,25.0,0.0,0.0,0.0,0,0,3.0,0,0.0,0.0,0,47.5,0,0.0,0.0,0.0,0.0,20.0,0.0,20,0,0.0,92020,700.0,20.0,0.0,0,20.0,0.0,0,50.0,0,-20,140,10.0,1,30,0.0,0.0,1,,,,,,,,,,,,,,,,,,,,,,,,,,,,,,,,,,,,27.5,,35.7,41.4,,48.3,12.6,20.8,,,,,,,,,0.864,0.02,,,,,,,,,,,,,,,,,,,,,,,,,,,,,,,,,,,,
128,"Can, Karaman",,,,,,,,,94,Internal,"We did heat treatment to the as-extruded sample at 500C for 24 hours followed by water quenching, then ran the load bias test on the HT'ed sample.",0.0,0.0,0.0,0.0,0,0.0,0.0,0.0,0.0,0,0.0,0.0,0.0,0.0,0.0,0.0,0.0,0.0,0.0,0.0,24.5,0,25.0,0.0,0.0,0.0,0,0,3.0,0,0.0,0.0,0,47.5,0,0.0,0.0,0.0,0.0,20.0,0.0,20,0,0.0,92020,700.0,20.0,0.0,0,500.0,24.0,0,100.0,0,-20,140,10.0,3,30,0.0,0.0,1,,,,,,,,,,,,,,,,,,,,,,,,,,,,,,,,,,,,35,,51.6,54.3,,67,15.4,32,,,,,,,,,1.829,0.0126,,,,,,,,,,,,,,,,,,,,,,,,,,,,,,,,,,,,
129,"Can, Karaman",,,,,,,,,92,Internal,,0.0,0.0,0.0,0.0,0,0.0,0.0,0.0,0.0,0,0.0,0.0,0.0,0.0,0.0,0.0,0.0,0.0,0.0,0.0,24.5,0,25.0,0.0,0.0,0.0,0,0,3.0,0,0.0,0.0,0,47.5,0,0.0,0.0,0.0,0.0,20.0,0.0,20,0,0.0,92020,700.0,20.0,0.0,0,20.0,0.0,0,100.0,0,-20,140,10.0,2,30,0.0,0.0,1,,,,,,,,,,,,,,,,,,,,,,,,,,,,,,,,,,,,32.2,,41.3,47.4,,54.9,13.6,22.7,,,,,,,,,1.9788,0.06,,,,,,,,,,,,,,,,,,,,,,,,,,,,,,,,,,,,
130,"Can, Karaman",,,,,,,,,94,Internal,"We did heat treatment to the as-extruded sample at 500C for 24 hours followed by water quenching, then ran the load bias test on the HT'ed sample.",0.0,0.0,0.0,0.0,0,0.0,0.0,0.0,0.0,0,0.0,0.0,0.0,0.0,0.0,0.0,0.0,0.0,0.0,0.0,24.5,0,25.0,0.0,0.0,0.0,0,0,3.0,0,0.0,0.0,0,47.5,0,0.0,0.0,0.0,0.0,20.0,0.0,20,0,0.0,92020,700.0,20.0,0.0,0,500.0,24.0,0,150.0,0,-20,140,10.0,4,30,0.0,0.0,1,,,,,,,,,,,,,,,,,,,,,,,,,,,,,,,,,,,,38.9,,59,57.3,,72.4,13.4,33.5,,,,,,,,,2.1335,0.0508,,,,,,,,,,,,,,,,,,,,,,,,,,,,,,,,,,,,
[...]
4864,G. Hudish,"Influence of microstructure on the shape memory properties of two Ti-lean, Ni-Ti-Pt high temperature shape memory alloys",,PhD Thesis,,1-168,2013,,,,External,,0.0,0.0,0.0,0.0,0,0.0,0.0,0.0,0.0,0,0.0,0.0,0.0,0.0,0.0,0.0,0.0,0.0,0.0,0.0,30.5,0,0.0,0.0,21.0,0.0,0,0,0.0,0,0.0,0.0,0,48.5,0,0.0,0.0,0.0,0.0,1050.0,72.0,900,0,0.0,20,0.0,20.0,0.0,0,700.0,100.0,0,-50.0,0,75,500,30.0,3,30,0.0,0.0,1,,,,,,,,,,,,,,,,,,,,,,,,,,,,,,,,,,,,,,336.2473348,336.8171021,,,,,,,,,,,,,,,,,,,,,,,,,,,,,,,,,,,,,,,,,,,,,,,,,,
4865,G. Hudish,"Influence of microstructure on the shape memory properties of two Ti-lean, Ni-Ti-Pt high temperature shape memory alloys",,PhD Thesis,,1-168,2013,,,,External,,0.0,0.0,0.0,0.0,0,0.0,0.0,0.0,0.0,0,0.0,0.0,0.0,0.0,0.0,0.0,0.0,0.0,0.0,0.0,30.5,0,0.0,0.0,21.0,0.0,0,0,0.0,0,0.0,0.0,0,48.5,0,0.0,0.0,0.0,0.0,1050.0,72.0,900,0,0.0,20,0.0,20.0,0.0,0,650.0,1.0,0,-50.0,0,75,500,30.0,3,30,0.0,0.0,1,,,,,,,,,,,,,,,,,,,,,,,,,,,,,,,,,,,,,,337.782516,334.9168646,,,,,,,,,,,,,,,,,,,,,,,,,,,,,,,,,,,,,,,,,,,,,,,,,,
4866,G. Hudish,"Influence of microstructure on the shape memory properties of two Ti-lean, Ni-Ti-Pt high temperature shape memory alloys",,PhD Thesis,,1-168,2013,,,,External,,0.0,0.0,0.0,0.0,0,0.0,0.0,0.0,0.0,0,0.0,0.0,0.0,0.0,0.0,0.0,0.0,0.0,0.0,0.0,30.5,0,0.0,0.0,21.0,0.0,0,0,0.0,0,0.0,0.0,0,48.5,0,0.0,0.0,0.0,0.0,1050.0,72.0,900,0,0.0,20,0.0,20.0,0.0,0,550.0,100.0,0,-50.0,0,75,500,30.0,3,30,0.0,0.0,1,,,,,,,,,,,,,,,,,,,,,,,,,,,,,,,,,,,,,,338.8059701,342.8978622,,,,,,,,,,,,,,,,,,,,,,,,,,,,,,,,,,,,,,,,,,,,,,,,,,
4867,G. Hudish,"Influence of microstructure on the shape memory properties of two Ti-lean, Ni-Ti-Pt high temperature shape memory alloys",,PhD Thesis,,1-168,2013,,,,External,,0.0,0.0,0.0,0.0,0,0.0,0.0,0.0,0.0,0,0.0,0.0,0.0,0.0,0.0,0.0,0.0,0.0,0.0,0.0,30.5,0,0.0,0.0,21.0,0.0,0,0,0.0,0,0.0,0.0,0,48.5,0,0.0,0.0,0.0,0.0,1050.0,72.0,900,0,0.0,20,0.0,20.0,0.0,0,650.0,100.0,0,-50.0,0,75,500,30.0,3,30,0.0,0.0,1,,,,,,,,,,,,,,,,,,,,,,,,,,,,,,,,,,,,,,340.5970149,347.4584323,,,,,,,,,,,,,,,,,,,,,,,,,,,,,,,,,,,,,,,,,,,,,,,,,,
4868,G. Hudish,"Influence of microstructure on the shape memory properties of two Ti-lean, Ni-Ti-Pt high temperature shape memory alloys",,PhD Thesis,,1-168,2013,,,,External,,0.0,0.0,0.0,0.0,0,0.0,0.0,0.0,0.0,0,0.0,0.0,0.0,0.0,0.0,0.0,0.0,0.0,0.0,0.0,30.5,0,0.0,0.0,21.0,0.0,0,0,0.0,0,0.0,0.0,0,48.5,0,0.0,0.0,0.0,0.0,1050.0,72.0,900,0,0.0,20,0.0,20.0,0.0,0,700.0,100.0,0,-50.0,0,75,500,30.0,3,30,0.0,0.0,1,,,,,,,,,,,,,,,,,,,,,,,,,,,,,,,,,,,,,,348.5287846,348.5985748,,,,,,,,,,,,,,,,,,,,,,,,,,,,,,,,,,,,,,,,,,,,,,,,,,
4869,G. Hudish,"Influence of microstructure on the shape memory properties of two Ti-lean, Ni-Ti-Pt high temperature shape memory alloys",,PhD Thesis,,1-168,2013,,,,External,,0.0,0.0,0.0,0.0,0,0.0,0.0,0.0,0.0,0,0.0,0.0,0.0,0.0,0.0,0.0,0.0,0.0,0.0,0.0,30.5,0,0.0,0.0,21.0,0.0,0,0,0.0,0,0.0,0.0,0,48.5,0,0.0,0.0,0.0,0.0,1050.0,72.0,900,0,0.0,20,0.0,1300.0,100.0,0,600.0,100.0,0,-50.0,0,75,500,30.0,3,30,0.0,0.0,1,,,,,,,,,,,,,,,,,,,,,,,,,,,,,,,,,,,,,,349.2963753,353.9192399,,,,,,,,,,,,,,,,,,,,,,,,,,,,,,,,,,,,,,,,,,,,,,,,,,
4870,G. Hudish,"Influence of microstructure on the shape memory properties of two Ti-lean, Ni-Ti-Pt high temperature shape memory alloys",,PhD Thesis,,1-168,2013,,,,External,,0.0,0.0,0.0,0.0,0,0.0,0.0,0.0,0.0,0,0.0,0.0,0.0,0.0,0.0,0.0,0.0,0.0,0.0,0.0,30.5,0,0.0,0.0,21.0,0.0,0,0,0.0,0,0.0,0.0,0,48.5,0,0.0,0.0,0.0,0.0,1050.0,72.0,900,0,0.0,20,0.0,20.0,0.0,0,800.0,100.0,0,-50.0,0,75,500,30.0,3,30,0.0,0.0,1,,,,,,,,,,,,,,,,,,,,,,,,,,,,,,,,,,,,,,351.5991471,350.8788599,,,,,,,,,,,,,,,,,,,,,,,,,,,,,,,,,,,,,,,,,,,,,,,,,,
4871,G. Hudish,"Influence of microstructure on the shape memory properties of two Ti-lean, Ni-Ti-Pt high temperature shape memory alloys",,PhD Thesis,,1-168,2013,,,,External,,0.0,0.0,0.0,0.0,0,0.0,0.0,0.0,0.0,0,0.0,0.0,0.0,0.0,0.0,0.0,0.0,0.0,0.0,0.0,30.5,0,0.0,0.0,21.0,0.0,0,0,0.0,0,0.0,0.0,0,48.5,0,0.0,0.0,0.0,0.0,1050.0,72.0,900,0,0.0,20,0.0,20.0,0.0,0,600.0,100.0,0,-50.0,0,75,500,30.0,3,30,0.0,0.0,1,,,,,,,,,,,,,,,,,,,,,,,,,,,,,,,,,,,,,,355.1812367,360.760095,,,,,,,,,,,,,,,,,,,,,,,,,,,,,,,,,,,,,,,,,,,,,,,,,,
4872,G. Hudish,"Influence of microstructure on the shape memory properties of two Ti-lean, Ni-Ti-Pt high temperature shape memory alloys",,PhD Thesis,,1-168,2013,,,,External,,0.0,0.0,0.0,0.0,0,0.0,0.0,0.0,0.0,0,0.0,0.0,0.0,0.0,0.0,0.0,0.0,0.0,0.0,0.0,30.5,0,0.0,0.0,21.0,0.0,0,0,0.0,0,0.0,0.0,0,48.5,0,0.0,0.0,0.0,0.0,1050.0,72.0,900,0,0.0,20,0.0,20.0,0.0,0,20.0,0.0,0,0.0,0,75,500,30.0,3,30,0.0,0.0,1,,,,,,,,,,,,,,,,,,,,,,,,,,,,,,,,,,,,,,255,184,,,,,,,,,,,,,,,,,,,,,,,,,,,,,,,,,,,,,,,,,,,,,,,,,,
4873,G. Hudish,"Influence of microstructure on the shape memory properties of two Ti-lean, Ni-Ti-Pt high temperature shape memory alloys",,PhD Thesis,,1-168,2013,,,,External,,0.0,0.0,0.0,0.0,0,0.0,0.0,0.0,0.0,0,0.0,0.0,0.0,0.0,0.0,0.0,0.0,0.0,0.0,0.0,30.5,0,0.0,0.0,21.0,0.0,0,0,0.0,0,0.0,0.0,0,48.5,0,0.0,0.0,0.0,0.0,1050.0,72.0,900,0,0.0,20,0.0,20.0,0.0,0,500.0,1.0,0,0.0,0,75,500,30.0,3,30,0.0,0.0,1,,,,,,,,,,,,,,,,,,,,,,,,,,,,,,,,,,,,,,270,231,,,,,,,,,,,,,,,,,,,,,,,,,,,,,,,,,,,,,,,,,,,,,,,,,,
4874,G. Hudish,"Influence of microstructure on the shape memory properties of two Ti-lean, Ni-Ti-Pt high temperature shape memory alloys",,PhD Thesis,,1-168,2013,,,,External,,0.0,0.0,0.0,0.0,0,0.0,0.0,0.0,0.0,0,0.0,0.0,0.0,0.0,0.0,0.0,0.0,0.0,0.0,0.0,30.5,0,0.0,0.0,21.0,0.0,0,0,0.0,0,0.0,0.0,0,48.5,0,0.0,0.0,0.0,0.0,1050.0,72.0,900,0,0.0,20,0.0,20.0,0.0,0,550.0,1.0,0,0.0,0,75,500,30.0,3,30,0.0,0.0,1,,,,,,,,,,,,,,,,,,,,,,,,,,,,,,,,,,,,,,294,278,,,,,,,,,,,,,,,,,,,,,,,,,,,,,,,,,,,,,,,,,,,,,,,,,,
4875,G. Hudish,"Influence of microstructure on the shape memory properties of two Ti-lean, Ni-Ti-Pt high temperature shape memory alloys",,PhD Thesis,,1-168,2013,,,,External,,0.0,0.0,0.0,0.0,0,0.0,0.0,0.0,0.0,0,0.0,0.0,0.0,0.0,0.0,0.0,0.0,0.0,0.0,0.0,30.5,0,0.0,0.0,21.0,0.0,0,0,0.0,0,0.0,0.0,0,48.5,0,0.0,0.0,0.0,0.0,1050.0,72.0,900,0,0.0,20,0.0,20.0,0.0,0,500.0,100.0,0,0.0,0,75,500,30.0,3,30,0.0,0.0,1,,,,,,,,,,,,,,,,,,,,,,,,,,,,,,,,,,,,,,315,300,,,,,,,,,,,,,,,,,,,,,,,,,,,,,,,,,,,,,,,,,,,,,,,,,,
4876,G. Hudish,"Influence of microstructure on the shape memory properties of two Ti-lean, Ni-Ti-Pt high temperature shape memory alloys",,PhD Thesis,,1-168,2013,,,,External,,0.0,0.0,0.0,0.0,0,0.0,0.0,0.0,0.0,0,0.0,0.0,0.0,0.0,0.0,0.0,0.0,0.0,0.0,0.0,30.5,0,0.0,0.0,21.0,0.0,0,0,0.0,0,0.0,0.0,0,48.5,0,0.0,0.0,0.0,0.0,1050.0,72.0,900,0,0.0,20,0.0,1300.0,100.0,0,550.0,100.0,0,0.0,0,75,500,30.0,3,30,0.0,0.0,1,,,,,,,,,,,,,,,,,,,,,,,,,,,,,,,,,,,,,,324,332,,,,,,,,,,,,,,,,,,,,,,,,,,,,,,,,,,,,,,,,,,,,,,,,,,
4877,G. Hudish,"Influence of microstructure on the shape memory properties of two Ti-lean, Ni-Ti-Pt high temperature shape memory alloys",,PhD Thesis,,1-168,2013,,,,External,,0.0,0.0,0.0,0.0,0,0.0,0.0,0.0,0.0,0,0.0,0.0,0.0,0.0,0.0,0.0,0.0,0.0,0.0,0.0,30.5,0,0.0,0.0,21.0,0.0,0,0,0.0,0,0.0,0.0,0,48.5,0,0.0,0.0,0.0,0.0,1050.0,72.0,900,0,0.0,20,0.0,20.0,0.0,0,700.0,1.0,0,0.0,0,75,500,30.0,3,30,0.0,0.0,1,,,,,,,,,,,,,,,,,,,,,,,,,,,,,,,,,,,,,,325,324,,,,,,,,,,,,,,,,,,,,,,,,,,,,,,,,,,,,,,,,,,,,,,,,,,
4878,G. Hudish,"Influence of microstructure on the shape memory properties of two Ti-lean, Ni-Ti-Pt high temperature shape memory alloys",,PhD Thesis,,1-168,2013,,,,External,,0.0,0.0,0.0,0.0,0,0.0,0.0,0.0,0.0,0,0.0,0.0,0.0,0.0,0.0,0.0,0.0,0.0,0.0,0.0,30.5,0,0.0,0.0,21.0,0.0,0,0,0.0,0,0.0,0.0,0,48.5,0,0.0,0.0,0.0,0.0,1050.0,72.0,900,0,0.0,20,0.0,20.0,0.0,0,700.0,100.0,0,0.0,0,75,500,30.0,3,30,0.0,0.0,1,,,,,,,,,,,,,,,,,,,,,,,,,,,,,,,,,,,,,,330,334,,,,,,,,,,,,,,,,,,,,,,,,,,,,,,,,,,,,,,,,,,,,,,,,,,
4879,G. Hudish,"Influence of microstructure on the shape memory properties of two Ti-lean, Ni-Ti-Pt high temperature shape memory alloys",,PhD Thesis,,1-168,2013,,,,External,,0.0,0.0,0.0,0.0,0,0.0,0.0,0.0,0.0,0,0.0,0.0,0.0,0.0,0.0,0.0,0.0,0.0,0.0,0.0,30.5,0,0.0,0.0,21.0,0.0,0,0,0.0,0,0.0,0.0,0,48.5,0,0.0,0.0,0.0,0.0,1050.0,72.0,900,0,0.0,20,0.0,20.0,0.0,0,650.0,1.0,0,0.0,0,75,500,30.0,3,30,0.0,0.0,1,,,,,,,,,,,,,,,,,,,,,,,,,,,,,,,,,,,,,,332,334,,,,,,,,,,,,,,,,,,,,,,,,,,,,,,,,,,,,,,,,,,,,,,,,,,
4880,G. Hudish,"Influence of microstructure on the shape memory properties of two Ti-lean, Ni-Ti-Pt high temperature shape memory alloys",,PhD Thesis,,1-168,2013,,,,External,,0.0,0.0,0.0,0.0,0,0.0,0.0,0.0,0.0,0,0.0,0.0,0.0,0.0,0.0,0.0,0.0,0.0,0.0,0.0,30.5,0,0.0,0.0,21.0,0.0,0,0,0.0,0,0.0,0.0,0,48.5,0,0.0,0.0,0.0,0.0,1050.0,72.0,900,0,0.0,20,0.0,20.0,0.0,0,600.0,1.0,0,0.0,0,75,500,30.0,3,30,0.0,0.0,1,,,,,,,,,,,,,,,,,,,,,,,,,,,,,,,,,,,,,,332,321,,,,,,,,,,,,,,,,,,,,,,,,,,,,,,,,,,,,,,,,,,,,,,,,,,
4881,G. Hudish,"Influence of microstructure on the shape memory properties of two Ti-lean, Ni-Ti-Pt high temperature shape memory alloys",,PhD Thesis,,1-168,2013,,,,External,,0.0,0.0,0.0,0.0,0,0.0,0.0,0.0,0.0,0,0.0,0.0,0.0,0.0,0.0,0.0,0.0,0.0,0.0,0.0,30.5,0,0.0,0.0,21.0,0.0,0,0,0.0,0,0.0,0.0,0,48.5,0,0.0,0.0,0.0,0.0,1050.0,72.0,900,0,0.0,20,0.0,20.0,0.0,0,650.0,100.0,0,0.0,0,75,500,30.0,3,30,0.0,0.0,1,,,,,,,,,,,,,,,,,,,,,,,,,,,,,,,,,,,,,,333,347,,,,,,,,,,,,,,,,,,,,,,,,,,,,,,,,,,,,,,,,,,,,,,,,,,
4882,G. Hudish,"Influence of microstructure on the shape memory properties of two Ti-lean, Ni-Ti-Pt high temperature shape memory alloys",,PhD Thesis,,1-168,2013,,,,External,,0.0,0.0,0.0,0.0,0,0.0,0.0,0.0,0.0,0,0.0,0.0,0.0,0.0,0.0,0.0,0.0,0.0,0.0,0.0,30.5,0,0.0,0.0,21.0,0.0,0,0,0.0,0,0.0,0.0,0,48.5,0,0.0,0.0,0.0,0.0,1050.0,72.0,900,0,0.0,20,0.0,20.0,0.0,0,550.0,100.0,0,0.0,0,75,500,30.0,3,30,0.0,0.0,1,,,,,,,,,,,,,,,,,,,,,,,,,,,,,,,,,,,,,,333,340,,,,,,,,,,,,,,,,,,,,,,,,,,,,,,,,,,,,,,,,,,,,,,,,,,
4883,G. Hudish,"Influence of microstructure on the shape memory properties of two Ti-lean, Ni-Ti-Pt high temperature shape memory alloys",,PhD Thesis,,1-168,2013,,,,External,,0.0,0.0,0.0,0.0,0,0.0,0.0,0.0,0.0,0,0.0,0.0,0.0,0.0,0.0,0.0,0.0,0.0,0.0,0.0,30.5,0,0.0,0.0,21.0,0.0,0,0,0.0,0,0.0,0.0,0,48.5,0,0.0,0.0,0.0,0.0,1050.0,72.0,900,0,0.0,20,0.0,20.0,0.0,0,700.0,100.0,0,0.0,0,75,500,30.0,3,30,0.0,0.0,1,,,,,,,,,,,,,,,,,,,,,,,,,,,,,,,,,,,,,,343,347,,,,,,,,,,,,,,,,,,,,,,,,,,,,,,,,,,,,,,,,,,,,,,,,,,
4884,G. Hudish,"Influence of microstructure on the shape memory properties of two Ti-lean, Ni-Ti-Pt high temperature shape memory alloys",,PhD Thesis,,1-168,2013,,,,External,,0.0,0.0,0.0,0.0,0,0.0,0.0,0.0,0.0,0,0.0,0.0,0.0,0.0,0.0,0.0,0.0,0.0,0.0,0.0,30.5,0,0.0,0.0,21.0,0.0,0,0,0.0,0,0.0,0.0,0,48.5,0,0.0,0.0,0.0,0.0,1050.0,72.0,900,0,0.0,20,0.0,1300.0,100.0,0,600.0,100.0,0,0.0,0,75,500,30.0,3,30,0.0,0.0,1,,,,,,,,,,,,,,,,,,,,,,,,,,,,,,,,,,,,,,344,353,,,,,,,,,,,,,,,,,,,,,,,,,,,,,,,,,,,,,,,,,,,,,,,,,,
4885,G. Hudish,"Influence of microstructure on the shape memory properties of two Ti-lean, Ni-Ti-Pt high temperature shape memory alloys",,PhD Thesis,,1-168,2013,,,,External,,0.0,0.0,0.0,0.0,0,0.0,0.0,0.0,0.0,0,0.0,0.0,0.0,0.0,0.0,0.0,0.0,0.0,0.0,0.0,30.5,0,0.0,0.0,21.0,0.0,0,0,0.0,0,0.0,0.0,0,48.5,0,0.0,0.0,0.0,0.0,1050.0,72.0,900,0,0.0,20,0.0,20.0,0.0,0,800.0,100.0,0,0.0,0,75,500,30.0,3,30,0.0,0.0,1,,,,,,,,,,,,,,,,,,,,,,,,,,,,,,,,,,,,,,345,349,,,,,,,,,,,,,,,,,,,,,,,,,,,,,,,,,,,,,,,,,,,,,,,,,,
4886,G. Hudish,"Influence of microstructure on the shape memory properties of two Ti-lean, Ni-Ti-Pt high temperature shape memory alloys",,PhD Thesis,,1-168,2013,,,,External,,0.0,0.0,0.0,0.0,0,0.0,0.0,0.0,0.0,0,0.0,0.0,0.0,0.0,0.0,0.0,0.0,0.0,0.0,0.0,30.5,0,0.0,0.0,21.0,0.0,0,0,0.0,0,0.0,0.0,0,48.5,0,0.0,0.0,0.0,0.0,1050.0,72.0,900,0,0.0,20,0.0,20.0,0.0,0,600.0,100.0,0,0.0,0,75,500,30.0,3,30,0.0,0.0,1,,,,,,,,,,,,,,,,,,,,,,,,,,,,,,,,,,,,,,348,360,,,,,,,,,,,,,,,,,,,,,,,,,,,,,,,,,,,,,,,,,,,,,,,,,,
4887,"K.V. Ramaiah, C.N. Saikrishna, Gouthama, S.K. Bhaumik",Ni24.7Ti50.3Pd25.0 high temperature shape memory alloy with narrow thermal hysteresis and high thermal stability,,Materials and Design,56,78-83,2014,,,,External,,0.0,0.0,0.0,0.0,0,0.0,0.0,0.0,0.0,0,0.0,0.0,0.0,0.0,0.0,0.0,0.0,0.0,0.0,0.0,24.7,0,25.0,0.0,0.0,0.0,0,0,0.0,0,0.0,0.0,0,50.3,0,0.0,0.0,0.0,0.0,20.0,0.0,20,0,0.0,20,0.0,20.0,0.0,0,1050.0,24.0,0,0.0,0,150,230,30.0,3,30,0.0,0.0,1,,,,,,,,,,,,,,,,,,,,,,,,,,,,,,,,,,,,180.6,,192.5,192.9,,201.9,9.4,21.3,,,,,,,,,,,,,,,,,,,,,,,,,,,,,,,,,,,,,,,,,,,,,,
4888,"S. H. Hong, J. T. Kim, H. J. Park, Y. S. Kim, J. Y. Suh, Y. S. Na, K. R. Lim, C. H. Shim, J. M. Park and K. B. Kim","Influence of Zr content on phase formation, transition and mechanical behavior of Ni-Ti-Hf-Zr high temperature shape memory alloys",,Journal of Alloys and Compounds,692,77-85,2017,,,,External,,0.0,0.0,0.0,0.0,0,0.0,0.0,0.0,0.0,0,0.0,0.0,0.0,12.0,0.0,0.0,0.0,0.0,0.0,0.0,50.0,0,0.0,0.0,0.0,0.0,0,0,0.0,0,0.0,0.0,0,28.0,0,0.0,0.0,0.0,10.0,20.0,0.0,20,0,0.0,20,0.0,20.0,0.0,0,20.0,0.0,0,0.0,0,,,40.0,3,30,0.0,0.0,1,,,,,,,,,,,,,,,,,,,,,,,,,,,,,,,,,,,,190.8344227,,297.1525054,265.7799564,,386.912854,89.7603486,196.0784313,,,,,,,,,,,,,,,,,,,,,,,,,,,,,,,,,,,,,,,,,,,,,,
4889,"S. H. Hong, J. T. Kim, H. J. Park, Y. S. Kim, J. Y. Suh, Y. S. Na, K. R. Lim, C. H. Shim, J. M. Park and K. B. Kim","Influence of Zr content on phase formation, transition and mechanical behavior of Ni-Ti-Hf-Zr high temperature shape memory alloys",,Journal of Alloys and Compounds,692,77-85,2017,,,,External,,0.0,0.0,0.0,0.0,0,0.0,0.0,0.0,0.0,0,0.0,0.0,0.0,12.0,0.0,0.0,0.0,0.0,0.0,0.0,50.0,0,0.0,0.0,0.0,0.0,0,0,0.0,0,0.0,0.0,0,28.0,0,0.0,0.0,0.0,10.0,20.0,0.0,20,0,0.0,20,0.0,20.0,0.0,0,20.0,0.0,0,0.0,0,,,40.0,3,30,0.0,0.0,1,,,,,,,,,,,,,,,,,,,,,,,,,,,,,,,,,,,,190.8344227,,297.1525054,265.7799564,,386.912854,89.7603486,196.0784313,,,,,,,,,,,,,,,,,,,,,,,,,,,,,,,,,,,,,,,,,,,,,,
4890,"S. H. Hong, J. T. Kim, H. J. Park, Y. S. Kim, J. Y. Suh, Y. S. Na, K. R. Lim, C. H. Shim, J. M. Park and K. B. Kim","Influence of Zr content on phase formation, transition and mechanical behavior of Ni-Ti-Hf-Zr high temperature shape memory alloys",,Journal of Alloys and Compounds,692,77-85,2017,,,,External,,0.0,0.0,0.0,0.0,0,0.0,0.0,0.0,0.0,0,0.0,0.0,0.0,12.0,0.0,0.0,0.0,0.0,0.0,0.0,50.0,0,0.0,0.0,0.0,0.0,0,0,0.0,0,0.0,0.0,0,23.0,0,0.0,0.0,0.0,15.0,20.0,0.0,20,0,0.0,20,0.0,20.0,0.0,0,20.0,0.0,0,0.0,0,,,40.0,3,30,0.0,0.0,1,,,,,,,,,,,,,,,,,,,,,,,,,,,,,,,,,,,,,,,557.7428767,,604.6494604,,,,,,,,,,,,,,,,,,,,,,,,,,,,,,,,,,,,,,,,,,,,,,,,
4891,"S. H. Hong, J. T. Kim, H. J. Park, Y. S. Kim, J. Y. Suh, Y. S. Na, K. R. Lim, C. H. Shim, J. M. Park and K. B. Kim","Influence of Zr content on phase formation, transition and mechanical behavior of Ni-Ti-Hf-Zr high temperature shape memory alloys",,Journal of Alloys and Compounds,692,77-85,2017,,,,External,,0.0,0.0,0.0,0.0,0,0.0,0.0,0.0,0.0,0,0.0,0.0,0.0,12.0,0.0,0.0,0.0,0.0,0.0,0.0,50.0,0,0.0,0.0,0.0,0.0,0,0,0.0,0,0.0,0.0,0,23.0,0,0.0,0.0,0.0,15.0,20.0,0.0,20,0,0.0,20,0.0,20.0,0.0,0,20.0,0.0,0,0.0,0,,,40.0,3,30,0.0,0.0,1,,,,,,,,,,,,,,,,,,,,,,,,,,,,,,,,,,,,,,,557.7428767,,604.6494604,,,,,,,,,,,,,,,,,,,,,,,,,,,,,,,,,,,,,,,,,,,,,,,,
4892,"S. H. Hong, J. T. Kim, H. J. Park, Y. S. Kim, J. Y. Suh, Y. S. Na, K. R. Lim, C. H. Shim, J. M. Park and K. B. Kim","Influence of Zr content on phase formation, transition and mechanical behavior of Ni-Ti-Hf-Zr high temperature shape memory alloys",,Journal of Alloys and Compounds,692,77-85,2017,,,,External,,0.0,0.0,0.0,0.0,0,0.0,0.0,0.0,0.0,0,0.0,0.0,0.0,12.0,0.0,0.0,0.0,0.0,0.0,0.0,50.0,0,0.0,0.0,0.0,0.0,0,0,0.0,0,0.0,0.0,0,35.0,0,0.0,0.0,0.0,3.0,20.0,0.0,20,0,0.0,20,0.0,20.0,0.0,0,20.0,0.0,0,0.0,0,,,40.0,3,30,0.0,0.0,1,,,,,,,,,,,,,,,,,,,,,,,,,,,,,,,,,,,,,,,156.0712613,,224.3048592,,,,,,,,,,,,,,,,,,,,,,,,,,,,,,,,,,,,,,,,,,,,,,,,
4893,"S. H. Hong, J. T. Kim, H. J. Park, Y. S. Kim, J. Y. Suh, Y. S. Na, K. R. Lim, C. H. Shim, J. M. Park and K. B. Kim","Influence of Zr content on phase formation, transition and mechanical behavior of Ni-Ti-Hf-Zr high temperature shape memory alloys",,Journal of Alloys and Compounds,692,77-85,2017,,,,External,,0.0,0.0,0.0,0.0,0,0.0,0.0,0.0,0.0,0,0.0,0.0,0.0,12.0,0.0,0.0,0.0,0.0,0.0,0.0,50.0,0,0.0,0.0,0.0,0.0,0,0,0.0,0,0.0,0.0,0,35.0,0,0.0,0.0,0.0,3.0,20.0,0.0,20,0,0.0,20,0.0,20.0,0.0,0,20.0,0.0,0,0.0,0,,,40.0,3,30,0.0,0.0,1,,,,,,,,,,,,,,,,,,,,,,,,,,,,,,,,,,,,,,,156.0712613,,224.3048592,,,,,,,,,,,,,,,,,,,,,,,,,,,,,,,,,,,,,,,,,,,,,,,,
4894,"S. H. Hong, J. T. Kim, H. J. Park, Y. S. Kim, J. Y. Suh, Y. S. Na, K. R. Lim, C. H. Shim, J. M. Park and K. B. Kim","Influence of Zr content on phase formation, transition and mechanical behavior of Ni-Ti-Hf-Zr high temperature shape memory alloys",,Journal of Alloys and Compounds,692,77-85,2017,,,,External,,0.0,0.0,0.0,0.0,0,0.0,0.0,0.0,0.0,0,0.0,0.0,0.0,12.0,0.0,0.0,0.0,0.0,0.0,0.0,50.0,0,0.0,0.0,0.0,0.0,0,0,0.0,0,0.0,0.0,0,31.0,0,0.0,0.0,0.0,7.0,20.0,0.0,20,0,0.0,20,0.0,20.0,0.0,0,20.0,0.0,0,0.0,0,,,40.0,3,30,0.0,0.0,1,,,,,,,,,,,,,,,,,,,,,,,,,,,,,,,,,,,,,,,155.8656998,,239.7562382,,,,,,,,,,,,,,,,,,,,,,,,,,,,,,,,,,,,,,,,,,,,,,,,
4895,"S. H. Hong, J. T. Kim, H. J. Park, Y. S. Kim, J. Y. Suh, Y. S. Na, K. R. Lim, C. H. Shim, J. M. Park and K. B. Kim","Influence of Zr content on phase formation, transition and mechanical behavior of Ni-Ti-Hf-Zr high temperature shape memory alloys",,Journal of Alloys and Compounds,692,77-85,2017,,,,External,,0.0,0.0,0.0,0.0,0,0.0,0.0,0.0,0.0,0,0.0,0.0,0.0,12.0,0.0,0.0,0.0,0.0,0.0,0.0,50.0,0,0.0,0.0,0.0,0.0,0,0,0.0,0,0.0,0.0,0,31.0,0,0.0,0.0,0.0,7.0,20.0,0.0,20,0,0.0,20,0.0,20.0,0.0,0,20.0,0.0,0,0.0,0,,,40.0,3,30,0.0,0.0,1,,,,,,,,,,,,,,,,,,,,,,,,,,,,,,,,,,,,,,,155.8656998,,239.7562382,,,,,,,,,,,,,,,,,,,,,,,,,,,,,,,,,,,,,,,,,,,,,,,,
4896,"X. L. Meng, H. Li, W. Cai, S. J. Hao and L. S. Cui",Thermal cycling stability mechanism of Ti50.5Ni33.5Cu11.5Pd4.5 shape memory alloy with near-zero hysteresis,,Scripta Materialia,103,30-33,2015,,,,External,,0.0,0.0,0.0,0.0,0,0.0,0.0,0.0,11.5,0,0.0,0.0,0.0,0.0,0.0,0.0,0.0,0.0,0.0,0.0,33.5,0,4.5,0.0,0.0,0.0,0,0,0.0,0,0.0,0.0,0,50.5,0,0.0,0.0,0.0,0.0,20.0,0.0,20,0,0.0,20,0.0,20.0,0.0,0,950.0,2.0,0,0.0,0,,,50.0,1,30,0.0,0.0,1,,,,,,,,,,,,,,,,,,,,,,,,,,,,,,,,,,,,,,,,,,,,,,,,,,,,,,,,,,,,,,,,,,,,,,,,,,,,,,,,,,,,,,,,,
4897,"X.L. Meng, H. Li, W. Cai, S.J. Hao, L.S. Cui",Thermal cycling stability mechanism of Ti50.5Ni33.5Cu11.5Pd4.5 shape memory alloy with near-zero hysteresis,,Scripta Metallurgica et Materialia,103,30-33,2015,,,,External,,0.0,0.0,0.0,0.0,0,0.0,0.0,0.0,11.5,0,0.0,0.0,0.0,0.0,0.0,0.0,0.0,0.0,0.0,0.0,33.5,0,4.5,0.0,0.0,0.0,0,0,0.0,0,0.0,0.0,0,50.5,0,0.0,0.0,0.0,0.0,20.0,0.0,20,0,0.0,20,0.0,20.0,0.0,0,950.0,2.0,0,0.0,0,,,50.0,1,30,0.0,0.0,1,,,,,,,,,,,,,,,,,,,,,,,,,,,,,,,,,,,,,,,,,,,,,,,,,,,,,,,,,,,,,,,,,,,,,,,,,,,,,,,,,,,,,,,,,
4898,"X. L. Meng, H. Li, W. Cai, S. J. Hao and L. S. Cui",Thermal cycling stability mechanism of Ti50.5Ni33.5Cu11.5Pd4.5 shape memory alloy with near-zero hysteresis,,Scripta Materialia,103,30-33,2015,,,,External,,0.0,0.0,0.0,0.0,0,0.0,0.0,0.0,11.5,0,0.0,0.0,0.0,0.0,0.0,0.0,0.0,0.0,0.0,0.0,33.5,0,4.5,0.0,0.0,0.0,0,0,0.0,0,0.0,0.0,0,50.5,0,0.0,0.0,0.0,0.0,20.0,0.0,20,0,0.0,20,0.0,20.0,0.0,0,950.0,2.0,0,0.0,0,,,100.0,1,30,0.0,0.0,1,,,,,,,,,,,,,,,,,,,,,,,,,,,,,,,,,,,,,,,,,,,,,,,,,,,,,,,,,,,,,,,,,,,,,,,,,,,,,,,,,,,,,,,,,
4899,"X.L. Meng, H. Li, W. Cai, S.J. Hao, L.S. Cui",Thermal cycling stability mechanism of Ti50.5Ni33.5Cu11.5Pd4.5 shape memory alloy with near-zero hysteresis,,Scripta Metallurgica et Materialia,103,30-33,2015,,,,External,,0.0,0.0,0.0,0.0,0,0.0,0.0,0.0,11.5,0,0.0,0.0,0.0,0.0,0.0,0.0,0.0,0.0,0.0,0.0,33.5,0,4.5,0.0,0.0,0.0,0,0,0.0,0,0.0,0.0,0,50.5,0,0.0,0.0,0.0,0.0,20.0,0.0,20,0,0.0,20,0.0,20.0,0.0,0,950.0,2.0,0,0.0,0,,,100.0,1,30,0.0,0.0,1,,,,,,,,,,,,,,,,,,,,,,,,,,,,,,,,,,,,,,,,,,,,,,,,,,,,,,,,,,,,,,,,,,,,,,,,,,,,,,,,,,,,,,,,,